Workbook

Sheet Engagement Dashboard
A1: DASHBOARD
A3: SESSION ACTIVITY | D3: MONTHLY PULSE RATINGS | G3: ACTIVE ALERTS
A4: Total Sessions Logged | B4: =COUNTA('Session Logs'!A3:A4997) -> 1 | D4: Avg Meeting Value (Q1 /5) | E4: =IFERROR(AVERAGE('Monthly Pulse Logs'!F3:F4997),"–") -> – | G4: Alert Type | H4: Threshold | I4: Current Value | J4: Status
A5: Sessions – This Month | B5: =COUNTIFS('Session Logs'!$E$3:$E$4997,">="&DATE(YEAR(TODAY()),MONTH(TODAY()),1),'Session Logs'!$E$3:$E$4997,"<="&TODAY()) -> 0 | D5: Avg Goal Progress (Q2 /5) | E5: =IFERROR(AVERAGE('Monthly Pulse Logs'!G3:G4997),"–") -> – | G5: Low Meeting Value | H5: < 3.0 avg | I5: =IFERROR(AVERAGE('Monthly Pulse Logs'!F3:F4997),"No data") -> No data | J5: =IF(ISNUMBER(I5),IF(I5<3,"🔴 ACTION NEEDED","✅ OK"),"–") -> –
A6: Unique Interns with Sessions | B6: =IFERROR(SUMPRODUCT(1/COUNTIF('Session Logs'!D3:D4997,'Session Logs'!D3:D4997)*('Session Logs'!D3:D4997<>"")),"–") -> – | D6: Avg Support Felt (Q3 /5) | E6: =IFERROR(AVERAGE('Monthly Pulse Logs'!H3:H4997),"–") -> – | G6: Low Goal Progress | H6: < 3.0 avg | I6: =IFERROR(AVERAGE('Monthly Pulse Logs'!G3:G4997),"No data") -> No data | J6: =IF(ISNUMBER(I6),IF(I6<3,"🔴 ACTION NEEDED","✅ OK"),"–") -> –
A7: Sessions with Concerns | B7: =COUNTIF('Session Logs'!K3:K4997,"Yes") -> 0 | D7: Avg Next-Step Clarity (Q4 /5) | E7: =IFERROR(AVERAGE('Monthly Pulse Logs'!I3:I4997),"–") -> – | G7: Low Support Felt | H7: < 3.0 avg | I7: =IFERROR(AVERAGE('Monthly Pulse Logs'!H3:H4997),"No data") -> No data | J7: =IF(ISNUMBER(I7),IF(I7<3,"🔴 ACTION NEEDED","✅ OK"),"–") -> –
A8: Avg Days Between Sessions | B8: – | D8: % Meeting 2x+ per Month | E8: =IFERROR((COUNTIF('Monthly Pulse Logs'!J3:J4997,"2")+COUNTIF('Monthly Pulse Logs'!J3:J4997,"3+"))/COUNTA('Monthly Pulse Logs'!J3:J4997),"–") -> – | G8: Overdue Sessions | H8: > 0 interns | I8: =COUNTIF('Intern Monitoring'!G4:G203,"Overdue – Book Now") -> 0 | J8: =IF(I8>0,"🟡 FOLLOW UP","✅ OK") -> ✅ OK
G9: Missed Sessions | H9: > 0 interns | I9: =COUNTIF('Intern Monitoring'!G4:G203,"Missed Session") -> 0 | J9: =IF(I9>0,"🔴 ACTION NEEDED","✅ OK") -> ✅ OK
G10: Concerns Flagged (Pulse) | H10: > 0 this month | I10: =COUNTIF('Monthly Pulse Logs'!M3:M4997,"Yes") -> 0 | J10: =IF(I10>0,"🔴 FOLLOW UP","✅ OK") -> ✅ OK
G11: Low 2x Meeting Rate | H11: < 60% of pairs | I11: =IFERROR((COUNTIF('Monthly Pulse Logs'!J3:J4997,"2")+COUNTIF('Monthly Pulse Logs'!J3:J4997,"3+"))/COUNTA('Monthly Pulse Logs'!J3:J4997),"No data") -> No data | J11: =IF(ISNUMBER(I11),IF(I11<0.6,"🟡 FOLLOW UP","✅ OK"),"–") -> –

Sheet Cohorts
A1: Cohort Name | B1: Start Date | C1: End Date | D1: Status | E1: Intern Count | F1: Notes
A2: Cohort 1 - 2026 | B2: 01/01/2026 | C2: 30/04/2026 | D2: Active | E2: =COUNTIF('Intern Profiles'!C4:C303,A2) -> 63 | F2: Q1 intake
A3: Cohort 2 - 2026 | B3: 01/05/2026 | C3: 31/08/2026 | D3: Planned | E3: =COUNTIF('Intern Profiles'!C4:C303,A3) -> 0 | F3: Q2 intake
A4: Cohort 3 - 2026 | B4: 01/09/2026 | C4: 31/12/2026 | D4: Planned | E4: =COUNTIF('Intern Profiles'!C4:C303,A4) -> 0 | F4: Q3 intake
B7: Active Cohort: | C7: =IFERROR(INDEX(A2:A4,MATCH("Active",D2:D4,0)),"No Active Cohort") -> Cohort 1 - 2026

Sheet Paste - Mentors
A1: 📥 PASTE MENTOR LISTING HERE (Workday Export — Monthly)
A2: Keep headers in row 3. Replace data from row 4 downwards each month.
A3: Employee ID | B3: Employee | C3: Available to Mentor | D3: Mentor Types | E3: Location Address - Country | F3: Franchise | G3: Supervisory Organization | H3: Cost Center | I3: Employee Type | J3: Job Family Group | K3: Job Title | L3: Worker's Tenure At Company | M3: Age Group | N3: Gender (Locale Sensitive) | O3: Race/Ethnicity (Locale Sensitive and Country Securable)
A4: 5183472 | B4: Gerald Maunda | C4: Yes | D4: Career Mentor | E4: Zambia | F4: FNB | G4: FNB Zambia Operations (Mubukwanu Mutiti (Inherited)) | H4: 55300003086 FNB Zambia Operations | I4: Full Time Employee | J4: Process, Operations and Administration | K4: Administration Assistant | L4: 4 year(s), 6 month(s), 23 day(s) | M4: 30 - 39 | N4: Male | O4: N/A (Zambia)
A5: 5495989 | B5: Bonolo Molebatsi | C5: Yes | D5: Career Mentor | E5: Botswana | F5: FNB | G5: FNB Botswana Channels (Mpho Nthutang) | H5: 501071600 FNB Botswana Kanye Branch | I5: Full Time Employee | J5: Sales and Client Services | K5: Sales and Service Consultant | L5: 3 year(s), 5 month(s), 23 day(s) | M5: 30 - 39 | N5: Female | O5: African (Botswana)
A6: 5009642 | B6: Otisitswe Faith Rathedi | C6: Yes | D6: Career Mentor Leadership Mentor | E6: Botswana | F6: FNB | G6: FNB Botswana Marketing and Communications (Peo Porogo) | H6: 5010152700 FNB Botswana Marketing and Communications | I6: Full Time Employee | J6: Marketing and Communication | K6: Marketing Manager | L6: 7 year(s), 8 month(s), 23 day(s) | M6: 30 - 39 | N6: Female | O6: African (Botswana)
A7: 5109140 | B7: Bydon Longwe | C7: Yes | D7: Career Mentor | E7: South Africa | F7: FNB | G7: FNB Chief Executive Office (Harry Kellan) | H7: 83300001939 FNB Executives | I7: Expatriate - In | J7: Process, Operations and Administration | K7: Chief Executive Officer Broader Africa | L7: 8 year(s), 0 month(s), 24 day(s) | M7: 50 - 59 | N7: Male | O7: African (South Africa)
A8: 4946073 | B8: Patrick Bontsibokae | C8: Yes | D8: Career Mentor | E8: Botswana | F8: FNB | G8: FNB Botswana Commercial (Tiro Kgasa) | H8: 5010160150 FNB Botswana Commercial SME Banking | I8: Full Time Employee | J8: Sales and Client Services | K8: Relationship Manager | L8: 6 year(s), 11 month(s), 12 day(s) | M8: 30 - 39 | N8: Male | O8: African (Botswana)
A9: 4997751 | B9: Caroline Kepaletswe | C9: Yes | D9: Career Mentor | E9: Botswana | F9: FNB | G9: FNB Rand Merchant Bank Botswana (Harriet Mlalazi) | H9: 5010160660 FNB Botswana Service Centre | I9: Full Time Employee | J9: Sales and Client Services | K9: Service Head | L9: 9 year(s), 8 month(s), 3 day(s) | M9: 40 - 49 | N9: Female
A10: 4714849 | B10: Chapita Mbuzi | C10: Yes | D10: Career Mentor | E10: Zambia | F10: FNB | G10: FNB Zambia Retail Segment (Chileshe Bwali-sakala) | H10: 55300016152 FNB Zambia Corporate Sales | I10: Full Time Employee | J10: Sales and Client Services | K10: Relationship Manager | L10: 12 year(s), 5 month(s), 23 day(s) | M10: 40 - 49 | N10: Male | O10: N/A (Zambia)
A11: 3872521 | B11: Wiza Phiri | C11: Yes | D11: Career Mentor | E11: Zambia | F11: FNB | G11: FNB Zambia Credit (Martin Mukonje) | H11: 55300003075 FNB Zambia Credit | I11: Full Time Employee | J11: Credit | K11: Credit Analyst | L11: 13 year(s), 9 month(s), 23 day(s) | M11: 30 - 39 | N11: Female
A12: 4930088 | B12: Retselisitsoe Sylvia Khet'semane | C12: Yes | D12: Career Mentor | E12: Lesotho | F12: FNB | G12: FNB Lesotho (Lehlohonolo Seitlheko) | H12: 51800000189 FNB Lesotho Pioneer Branch | I12: Full Time Employee | J12: Sales and Client Services | K12: Client Service Representative | L12: 9 year(s), 10 month(s), 23 day(s) | M12: 30 - 39 | N12: Female | O12: African (Lesotho)
A13: 4989171 | B13: Borethe Mogwe | C13: Yes | D13: Career Mentor | E13: Botswana | F13: FNB | G13: FNB Botswana Wealth (Tshepiso Scheffers) | H13: 5010160500 FNB Botswana Consumer Banking | I13: Full Time Employee | J13: Product | K13: Customer Value Proposition Manager | L13: 9 year(s), 9 month(s), 9 day(s) | M13: 30 - 39 | N13: Female | O13: African (Botswana)
A14: 4804473 | B14: Gofaone Mokalake | C14: Yes | D14: Career Mentor Leadership Mentor | E14: Botswana | F14: FNB | G14: FNB Botswana Executive Suite (Onkarabile Kono) | H14: 5010164200 FNB Botswana Client Services | I14: Full Time Employee | J14: Sales and Client Services | K14: Service Manager | L14: 10 year(s), 10 month(s), 23 day(s) | M14: 40 - 49 | N14: Female | O14: African (Botswana)
A15: 4868455 | B15: Tshepo Sentle | C15: Yes | D15: Career Mentor | E15: Botswana | F15: FNB | G15: FNB Botswana Commercial (Thapelo Kamodi) | H15: 5010717300 FNB Botswana Cash Plus | I15: Full Time Employee | J15: Sales and Client Services | K15: Cash Plus Banker | L15: 10 year(s), 9 month(s), 23 day(s) | M15: 30 - 39 | N15: Male
A16: 4873033 | B16: Collen Tshebo | C16: Yes | D16: Career Mentor Leadership Mentor Technical Mentor Transition Mentor Workplace Buddy | E16: Botswana | F16: FNB | G16: FNB Botswana Business Support WesBank (Goeme Ganetsang) | H16: 5010394500 FNB Botswana Business Support | I16: Full Time Employee | J16: Sales and Client Services | K16: Client Portfolio Analyst | L16: 10 year(s), 5 month(s), 9 day(s) | M16: 30 - 39 | N16: Male
A17: 2893622 | B17: Mothibi Tangane | C17: Yes | D17: Career Mentor | E17: Botswana | F17: FNB | G17: FNB Botswana Operations (Nonofo Molwane) | H17: 501070500 FNB Botswana Cash Centre | I17: Full Time Employee | J17: Process, Operations and Administration | K17: Cash Operations Manager | L17: 22 year(s), 7 month(s), 13 day(s) | M17: 40 - 49 | N17: Male
A18: 4633369 | B18: Chipo Mwenya | C18: Yes | D18: Career Mentor | E18: Zambia | F18: FNB | G18: FNB Zambia Retail Segment (Jeremiah Namitondo) | H18: 55300009179 FNB Zambia Choma Branch | I18: Full Time Employee | J18: Sales and Client Services | K18: Branch Manager | L18: 12 year(s), 8 month(s), 2 day(s) | M18: 30 - 39 | N18: Female
A19: 3246388 | B19: Phetso Ntsowe | C19: Yes | D19: Career Mentor Leadership Mentor | E19: Botswana | F19: FNB | G19: FNB Botswana Retail Banking (Boniface Seane) | H19: 5010292200 FNB Botswana Channels Head Office | I19: Full Time Employee | J19: Legal, Risk and Compliance | K19: Risk Manager | L19: 17 year(s), 6 month(s), 16 day(s) | M19: 40 - 49 | N19: Female
A20: 3330370 | B20: Likenkeng Lylian Morojele | C20: Yes | D20: Career Mentor | E20: Lesotho | F20: FNB | G20: FNB Lesotho (Fusi Sefatsane) | H20: 51800001851 FNB Lesotho Kingway Branch | I20: Full Time Employee | J20: Sales and Client Services | K20: Branch Manager | L20: 17 year(s), 3 month(s), 2 day(s) | M20: 30 - 39 | N20: Female | O20: African (Lesotho)
A21: 4739736 | B21: Neo Thebeng-Phuthego | C21: Yes | D21: Career Mentor | E21: Botswana | F21: FNB | G21: FNB Botswana Audit Management (Theetso Nkwe) | H21: 5010166100 FNB Botswana Audit | I21: Full Time Employee | J21: Legal, Risk and Compliance | K21: Senior Audit Manager | L21: 12 year(s), 2 month(s), 23 day(s) | M21: 40 - 49 | N21: Female
A22: 4827430 | B22: Stephinah Magetse | C22: Yes | D22: Career Mentor | E22: Botswana | F22: FNB | G22: FNB Botswana Channels (Benni Dikobe) | H22: 501073600 FNB Botswana Mall Branch | I22: Full Time Employee | J22: Sales and Client Services | K22: Branch Manager | L22: 11 year(s), 4 month(s), 25 day(s) | M22: 50 - 59 | N22: Female
A23: 3243605 | B23: Baile Corrigan | C23: Yes | D23: Career Mentor | E23: Botswana | F23: FNB | G23: FNB Rand Merchant Bank Botswana (Harriet Mlalazi) | H23: 5010342500 RMB Botswana Flow Risk | I23: Full Time Employee | J23: Capital Markets and Invest | K23: Global Market Head | L23: 10 year(s), 8 month(s), 11 day(s) | M23: 40 - 49 | N23: Female
A24: 5436346 | B24: Billy Samuel Mwape | C24: Yes | D24: Career Mentor Leadership Mentor Transition Mentor Workplace Buddy | E24: Zambia | F24: FNB | G24: FNB Zambia Chief Executive Office (Kapumpe Chola) | H24: 55300003079 FNB Zambia Information Technology | I24: Full Time Employee | J24: Technology | K24: Chief Information Officer | L24: 4 year(s), 6 month(s), 4 day(s) | M24: 40 - 49 | N24: Male | O24: N/A (Zambia)
A25: 5066220 | B25: Jj Jongman | C25: Yes | D25: Career Mentor | E25: Botswana | F25: FNB | G25: FNB Botswana Human Capital (Kaone Kopi) | H25: 5010152800 FNB Botswana Human Capital | I25: Full Time Employee | J25: Human Capital | K25: Human Capital Business Partner | L25: 8 year(s), 7 month(s), 23 day(s) | M25: 40 - 49 | N25: Male | O25: African (Botswana)
A26: 5385571 | B26: Mwamba Musambo | C26: Yes | D26: Career Mentor | E26: Zambia | F26: FNB | G26: FNB Zambia Chief Executive Office (Kapumpe Chola) | H26: 55300003061 FNB Zambia Retail Segment | I26: Full Time Employee | J26: Sales and Client Services | K26: Retail Banking Executive | L26: 5 year(s), 0 month(s), 27 day(s) | M26: 40 - 49 | N26: Female
A27: 5101646 | B27: Charity Mubitelela | C27: Yes | E27: Zambia | F27: FNB | G27: FNB Zambia Retail Segment (Mike Nyimbili) | H27: 55300003645 FNB Zambia Kasama Branch | I27: Full Time Employee | J27: Sales and Client Services | K27: Multi Skilled Consultant | L27: 8 year(s), 2 month(s), 0 day(s) | M27: 30 - 39 | N27: Female
A28: 4974220 | B28: Kgosi Modisaeman | C28: Yes | D28: Career Mentor Leadership Mentor Workplace Buddy | E28: Botswana | F28: FNB | G28: FNB Botswana Brokerage (Govern Maseba) | H28: 5010166400 FNB Botswana Brokerage | I28: Full Time Employee | J28: Finance | K28: Reconciliation Officer | L28: 8 year(s), 4 month(s), 23 day(s) | M28: 30 - 39 | N28: Male | O28: African (Botswana)
A29: 4904699 | B29: Mcintire Luke | C29: Yes | D29: Career Mentor | E29: Botswana | F29: FNB | G29: FNB Botswana Retail (One Molefe) | H29: 5010344300 FNB Botswana Wesbank Retail Segment | I29: Full Time Employee | J29: Sales and Client Services | K29: Business Development Officer | L29: 9 year(s), 7 month(s), 23 day(s) | M29: 30 - 39 | N29: Male | O29: African (Botswana)
A30: 5004608 | B30: Maleseli Lorraine Chefa | C30: Yes | D30: Leadership Mentor | E30: Lesotho | F30: FNB | G30: FNB Lesotho (Daniel Mohau) | H30: 51800001852 FNB Lesotho OPC | I30: Full Time Employee | J30: Process, Operations and Administration | K30: Team Leader Back Office | L30: 8 year(s), 10 month(s), 23 day(s) | M30: 30 - 39 | N30: Female | O30: African (Lesotho)
A31: 4846443 | B31: Kapumpe Chola | C31: Yes | D31: Career Mentor | E31: Zambia | F31: FNB | G31: FNB Broader Africa (Bydon Longwe) | H31: 55300004651 FNB Zambia FCC | I31: Full Time Employee | J31: Process, Operations and Administration | K31: Chief Executive Officer | L31: 11 year(s), 2 month(s), 18 day(s) | M31: 50 - 59 | N31: Female
A32: 4778561 | B32: Mike Nyimbili | C32: Yes | D32: Career Mentor | E32: Zambia | F32: FNB | G32: FNB Zambia Retail Segment (Njavwa Nakapizye) | H32: 55300003645 FNB Zambia Kasama Branch | I32: Full Time Employee | J32: Sales and Client Services | K32: Branch Manager | L32: 11 year(s), 9 month(s), 23 day(s) | M32: 30 - 39 | N32: Male
A33: 4846583 | B33: Alfred Mwanza | C33: Yes | D33: Career Mentor | E33: Zambia | F33: FNB | G33: FNB Zambia Compliance (Eugenius Hambokoma) | H33: 55300003087 FNB Zambia Compliance | I33: Full Time Employee | J33: Legal, Risk and Compliance | K33: Financial Crime Analyst | L33: 11 year(s), 0 month(s), 23 day(s) | M33: 30 - 39 | N33: Male
A34: 4847393 | B34: Ronald Mvula | C34: Yes | D34: Career Mentor | E34: Zambia | F34: FNB | G34: FNB Zambia Retail Segment (Kateule Musonda) | H34: 55300009187 FNB Zambia Lusaka Private Suite | I34: Full Time Employee | J34: Process, Operations and Administration | K34: Branch Administrator | L34: 11 year(s), 2 month(s), 18 day(s) | M34: 30 - 39 | N34: Male
A35: 3511235 | B35: Palesa Moeng | C35: Yes | D35: Career Mentor Leadership Mentor Technical Mentor Workplace Buddy | E35: Botswana | F35: FNB | G35: FNB Botswana Operations (Bookeditswe Matladi-Molebatsi) | H35: 5010343200 FNB Botswana RMB Operations | I35: Full Time Employee | J35: Finance | K35: Reconciliation Officer | L35: 13 year(s), 0 month(s), 23 day(s) | M35: 30 - 39 | N35: Female | O35: African (Botswana)
A36: 4784545 | B36: Lesego Nkepe | C36: Yes | D36: Career Mentor | E36: Botswana | F36: FNB | G36: FNB Botswana Retail (Serwalo Mabotho) | H36: 5010292200 FNB Botswana Channels Head Office | I36: Full Time Employee | J36: Sales and Client Services | K36: Service Manager | L36: 9 year(s), 6 month(s), 23 day(s) | M36: 30 - 39 | N36: Female
A37: 3244318 | B37: Lydia Oakile | C37: Yes | D37: Career Mentor | E37: Botswana | F37: FNB | G37: FNB Botswana Operations (Otile Olekantse) | H37: 5010123600 FNB Botswana Francistown Mini Cash Centre | I37: Full Time Employee | J37: Sales and Client Services | K37: Cash Centre Bulk Teller | L37: 18 year(s), 4 month(s), 23 day(s) | M37: 40 - 49 | N37: Female | O37: African (Botswana)
A38: 2815966 | B38: Kelebogile Disang | C38: Yes | D38: Career Mentor | E38: Botswana | F38: FNB | G38: FNB Botswana Commercial (Valentine Harward) | H38: 5010160140 FNB Botswana Commercial Sales P100M+ | I38: Full Time Employee | J38: Sales and Client Services | K38: Relationship Manager | L38: 24 year(s), 8 month(s), 21 day(s) | M38: 40 - 49 | N38: Female
A39: 3511847 | B39: Amantle Mphoeng | C39: Yes | D39: Career Mentor | E39: Botswana | F39: FNB | G39: FNB Botswana Operations (Lesego Tamajobe) | H39: 5010164100 FNB Botswana Call Centre | I39: Full Time Employee | J39: Sales and Client Services | K39: Service Manager | L39: 12 year(s), 8 month(s), 23 day(s) | M39: 30 - 39 | N39: Male
A40: 3506622 | B40: Tekolo Rasenyai | C40: Yes | D40: Career Mentor Leadership Mentor | E40: Botswana | F40: FNB | G40: FNB Botswana Enabler (Mike Rammelane) | H40: 5010151500 FNB Botswana Credit Head Office | I40: Full Time Employee | J40: Credit | K40: Credit Manager | L40: 16 year(s), 1 month(s), 23 day(s) | M40: 30 - 39 | N40: Female
...

Sheet Paste - Relationships
A1: 📥 PASTE RELATIONSHIP REPORT HERE (Workday Export — Monthly)
A2: Keep headers in row 3. Replace data from row 4 downwards each month.
A3: Mentor ID | B3: Mentor | C3: Purpose | D3: Mentor Type | E3: Mentor Employee Type | F3: Mentor Race | G3: Mentor Gender | H3: Mentor Age Group | I3: Mentor Supervisory Organization | J3: Mentor Location Country | K3: Mentor Franchise | L3: Mentor Cost Centre | M3: Mentor Job Title | N3: Mentor Tenure | O3: Mentor Job Family Group | P3: Mentee ID | Q3: Mentee | R3: Mentee Employee Type | S3: Mentee Race | T3: Mentee Gender | U3: Mentee Age Group | V3: Mentee Supervisory Organization | W3: Mentee Location Country | X3: Mentee Franchise | Y3: Mentee Cost Centre | Z3: Mentee Job Title | AA3: Mentee Tenure | AB3: Mentee Job Family Group | AC3: Mentorship Events | AD3: Start Date | AE3: End Date | AF3: Close Mentorship Reason
A4: 3246388 | B4: Phetso Ntsowe | C4: Develop your team leadership and self-leadership skills Train to be an effective leader | D4: Leadership Mentor | E4: Full Time Employee | G4: Female | H4: 40 - 49 | I4: FNB Botswana Retail Banking (Boniface Seane) | J4: Botswana | K4: FNB | L4: 5010292200 FNB Botswana Channels Head Office | M4: Risk Manager | N4: 16 - 20 Years | O4: Operational Risk | P4: 3509672 | Q4: Banyatsi Seeme | R4: Full Time Employee | S4: African (Botswana) | T4: Female | U4: 30 - 39 | V4: FNB Botswana Channels (Janet Morolong) | W4: Botswana | X4: FNB | Y4: 5010401100 FNB Botswana Mogoditshane Branch | Z4: Migration Official | AA4: 11 -15 Years | AB4: Client Experience and Value Management | AC4: Close Mentorship Event for Banyatsi Seeme with Phetso Ntsowe Create Mentorship Event for Banyatsi Seeme with Phetso Ntsowe Edit Mentorship Event for Banyatsi Seeme with Phetso Ntsowe | AD4: 45170 | AE4: 45351 | AF4: Mentee Withdrawal - Availability
A5: 5495989 | B5: Bonolo Molebatsi | D5: Career Mentor | E5: Full Time Employee | F5: African (Botswana) | G5: Female | H5: 30 - 39 | I5: FNB Botswana Channels (Mpho Nthutang) | J5: Botswana | K5: FNB | L5: 501071600 FNB Botswana Kanye Branch | M5: Sales and Service Consultant | N5: 3 - 5 Years | O5: Direct Sales | P5: 5549248 | Q5: Boago Thomas | R5: Full Time Employee | S5: African (Botswana) | T5: Female | U5: 30 - 39 | V5: FNB Botswana Channels (Lorato Mothibi) | W5: Botswana | X5: FNB | Y5: 5010401300 FNB Botswana Mochudi Branch | Z5: Migration Official | AA5: <1 Year | AB5: Client Experience and Value Management | AC5: Create Mentorship Event for Boago Thomas with Bonolo Molebatsi | AD5: 45125
A6: 3246388 | B6: Phetso Ntsowe | D6: Career Mentor | E6: Full Time Employee | G6: Female | H6: 40 - 49 | I6: FNB Botswana Retail Banking (Boniface Seane) | J6: Botswana | K6: FNB | L6: 5010292200 FNB Botswana Channels Head Office | M6: Risk Manager | N6: 16 - 20 Years | O6: Operational Risk | P6: 5599199 | Q6: Thuto Kofi (Terminated) | T6: Female | U6: 20 - 29 | W6: Botswana | AA6: <1 Year | AC6: Close Mentorship Event for Thuto Kofi (Terminated) with Phetso Ntsowe Create Mentorship Event for Thuto Kofi (Terminated) with Phetso Ntsowe Edit Mentorship Event for Thuto Kofi (Terminated) with Phetso Ntsowe | AD6: 45139 | AE6: 45351 | AF6: Mentee Withdrawal - Availability
A7: 3244121 | B7: Udah Otukile (Terminated) | C7: To help the employee in navigating their growth in the organisation as well as exploring various opportunities. | D7: Career Mentor | G7: Female | H7: 50 - 59 | J7: Botswana | N7: 6 - 10 Years | P7: 5389836 | Q7: Kabelo Sekoto | R7: Full Time Employee | S7: African (Botswana) | T7: Male | U7: 30 - 39 | V7: FNB Rand Merchant Bank Botswana (Therisanyo Masuga) | W7: Botswana | X7: FNB | Y7: 5010168800 FNB Botswana Corporate Segments | Z7: Product Analyst | AA7: 3 - 5 Years | AB7: Product Support, Development and Analysis | AC7: Create Mentorship Event for Kabelo Sekoto with Udah Otukile (Terminated) | AD7: 44835 | AE7: 45199
A8: 5066220 | B8: Jj Jongman | C8: To help ascend to a Managerial role or change portfolio from the current Premier Banker which is overwhelming. | D8: Career Mentor | E8: Full Time Employee | F8: African (Botswana) | G8: Male | H8: 40 - 49 | I8: FNB Botswana Human Capital (Kaone Kopi) | J8: Botswana | K8: FNB | L8: 5010152800 FNB Botswana Human Capital | M8: Human Capital Business Partner | N8: 6 - 10 Years | O8: Business Human Capital | P8: 5124387 | Q8: Pamela Ndlovu | R8: Full Time Employee | T8: Female | U8: 30 - 39 | V8: FNB Botswana Wealth (Donna Isaacs) | W8: Botswana | X8: FNB | Y8: 5010160210 FNB Botswana Retail Smart and Gold Sales | Z8: Premier Banker | AA8: 6 - 10 Years | AB8: Client Relationship Management | AC8: Create Mentorship Event for Pamela Ndlovu with Jj Jongman Edit Mentorship Event for Pamela Ndlovu with Jj Jongman Edit Mentorship Event for Pamela Ndlovu with Jj Jongman | AD8: 44927 | AE8: 45657
A9: 3246388 | B9: Phetso Ntsowe | C9: Career guidance Relationship building and networking. Manage a career transition. Develop leadership skills. | D9: Career Mentor | E9: Full Time Employee | G9: Female | H9: 40 - 49 | I9: FNB Botswana Retail Banking (Boniface Seane) | J9: Botswana | K9: FNB | L9: 5010292200 FNB Botswana Channels Head Office | M9: Risk Manager | N9: 16 - 20 Years | O9: Operational Risk | P9: 5179564 | Q9: Kefilwe Samson | R9: Full Time Employee | T9: Female | U9: 30 - 39 | V9: FNB Botswana Channels (Lebelelang Mabeo) | W9: Botswana | X9: FNB | Y9: 5010164100 FNB Botswana Call Centre | Z9: Sales Consultant | AA9: 6 - 10 Years | AB9: Direct Sales | AC9: Close Mentorship Event for Kefilwe Samson with Phetso Ntsowe Create Mentorship Event for Kefilwe Samson with Phetso Ntsowe Edit Mentorship Event for Kefilwe Samson with Phetso Ntsowe Edit Mentorship Event for Kefilwe Samson with Phetso Ntsowe | AD9: 45170 | AE9: 45351 | AF9: Mentor Withdrawal - Availability
A10: 5495989 | B10: Bonolo Molebatsi | C10: To take me the right department | D10: Career Mentor | E10: Full Time Employee | F10: African (Botswana) | G10: Female | H10: 30 - 39 | I10: FNB Botswana Channels (Mpho Nthutang) | J10: Botswana | K10: FNB | L10: 501071600 FNB Botswana Kanye Branch | M10: Sales and Service Consultant | N10: 3 - 5 Years | O10: Direct Sales | P10: 4773829 | Q10: Otlaadisa Mogosane | R10: Full Time Employee | T10: Male | U10: 30 - 39 | V10: FNB Botswana Channels (Nametsegang Muchina) | W10: Botswana | X10: FNB | Y10: 501073700 FNB Botswana Broadhurst Branch | Z10: Teller | AA10: 6 - 10 Years | AB10: Client Services Support and Delivery | AC10: Create Mentorship Event for Otlaadisa Mogosane with Bonolo Molebatsi | AD10: 45205 | AE10: 45260
A11: 3246388 | B11: Phetso Ntsowe | D11: Leadership Mentor | E11: Full Time Employee | G11: Female | H11: 40 - 49 | I11: FNB Botswana Retail Banking (Boniface Seane) | J11: Botswana | K11: FNB | L11: 5010292200 FNB Botswana Channels Head Office | M11: Risk Manager | N11: 16 - 20 Years | O11: Operational Risk | P11: 2700069 | Q11: Bontle Maeco | R11: Full Time Employee | T11: Female | U11: 50 - 59 | V11: FNB Botswana Channels (Rose Selema) | W11: Botswana | X11: FNB | Y11: 501071400 FNB Botswana Lobatse Branch | Z11: Teller Coordinator | AA11: >20 Years | AB11: Client Services Support and Delivery | AC11: Close Mentorship Event for Bontle Maeco with Phetso Ntsowe Create Mentorship Event for Bontle Maeco with Phetso Ntsowe Edit Mentorship Event for Bontle Maeco with Phetso Ntsowe | AD11: 45170 | AE11: 45351 | AF11: Mentee Withdrawal - Availability
A12: 3246388 | B12: Phetso Ntsowe | D12: Career Mentor | E12: Full Time Employee | G12: Female | H12: 40 - 49 | I12: FNB Botswana Retail Banking (Boniface Seane) | J12: Botswana | K12: FNB | L12: 5010292200 FNB Botswana Channels Head Office | M12: Risk Manager | N12: 16 - 20 Years | O12: Operational Risk | P12: 5042070 | Q12: Ivy Letus | R12: Full Time Employee | S12: Coloured (Botswana) | T12: Female | U12: 40 - 49 | V12: FNB Botswana Channels (Fiona Kasese) | W12: Botswana | X12: FNB | Y12: 5010150200 FNB Botswana Riverwalk Branch | Z12: Service Consultant | AA12: 6 - 10 Years | AB12: Client Experience and Value Management | AC12: Close Mentorship Event for Ivy Letus with Phetso Ntsowe Create Mentorship Event for Ivy Letus with Phetso Ntsowe Edit Mentorship Event for Ivy Letus with Phetso Ntsowe | AD12: 45170 | AE12: 45351 | AF12: Mentee Withdrawal - Availability
A13: 3246388 | B13: Phetso Ntsowe | D13: Transition Mentor | E13: Full Time Employee | G13: Female | H13: 40 - 49 | I13: FNB Botswana Retail Banking (Boniface Seane) | J13: Botswana | K13: FNB | L13: 5010292200 FNB Botswana Channels Head Office | M13: Risk Manager | N13: 16 - 20 Years | O13: Operational Risk | P13: 4773829 | Q13: Otlaadisa Mogosane | R13: Full Time Employee | T13: Male | U13: 30 - 39 | V13: FNB Botswana Channels (Nametsegang Muchina) | W13: Botswana | X13: FNB | Y13: 501073700 FNB Botswana Broadhurst Branch | Z13: Teller | AA13: 6 - 10 Years | AB13: Client Services Support and Delivery | AC13: Close Mentorship Event for Otlaadisa Mogosane with Phetso Ntsowe Create Mentorship Event for Otlaadisa Mogosane with Phetso Ntsowe | AD13: 45230 | AE13: 45260 | AF13: Mentee Withdrawal - Availability
A14: 3246388 | B14: Phetso Ntsowe | C14: MENTORSHIP | D14: Leadership Mentor | E14: Full Time Employee | G14: Female | H14: 40 - 49 | I14: FNB Botswana Retail Banking (Boniface Seane) | J14: Botswana | K14: FNB | L14: 5010292200 FNB Botswana Channels Head Office | M14: Risk Manager | N14: 16 - 20 Years | O14: Operational Risk | P14: 3506878 | Q14: Maipelo Daman | R14: Full Time Employee | T14: Female | U14: 30 - 39 | V14: FNB Botswana Channels (Mable Motsumi) | W14: Botswana | X14: FNB | Y14: 5010160300 FNB Botswana Airport Junction | Z14: Branch Delivery Sales and Service Team Leader | AA14: 16 - 20 Years | AB14: Direct Sales | AC14: Close Mentorship Event for Maipelo Daman with Phetso Ntsowe Create Mentorship Event for Maipelo Daman with Phetso Ntsowe | AD14: 45170 | AE14: 45351 | AF14: Mentee Withdrawal - Availability
A15: 3246388 | B15: Phetso Ntsowe | C15: mentorship | D15: Career Mentor | E15: Full Time Employee | G15: Female | H15: 40 - 49 | I15: FNB Botswana Retail Banking (Boniface Seane) | J15: Botswana | K15: FNB | L15: 5010292200 FNB Botswana Channels Head Office | M15: Risk Manager | N15: 16 - 20 Years | O15: Operational Risk | P15: 5000181 | Q15: Maureen Lucas | R15: Full Time Employee | S15: African (Botswana) | T15: Female | U15: 40 - 49 | V15: FNB Botswana Channels (Onneile Mogotsi) | W15: Botswana | X15: FNB | Y15: 501079200 FNB Botswana Kgale Branch | Z15: Sales and Service Consultant | AA15: 6 - 10 Years | AB15: Direct Sales | AC15: Close Mentorship Event for Maureen Lucas with Phetso Ntsowe Create Mentorship Event for Maureen Lucas with Phetso Ntsowe | AD15: 45170 | AE15: 45351 | AF15: Mentee Withdrawal - Availability
A16: 3246388 | B16: Phetso Ntsowe | D16: Leadership Mentor | E16: Full Time Employee | G16: Female | H16: 40 - 49 | I16: FNB Botswana Retail Banking (Boniface Seane) | J16: Botswana | K16: FNB | L16: 5010292200 FNB Botswana Channels Head Office | M16: Risk Manager | N16: 16 - 20 Years | O16: Operational Risk | P16: 3245489 | Q16: Masego Basupang | R16: Full Time Employee | S16: African (Botswana) | T16: Female | U16: 40 - 49 | V16: FNB Botswana Wealth (Tshepiso Scheffers) | W16: Botswana | X16: FNB | Y16: 5010209700 FNB Botswana Premier | Z16: Premier Banker | AA16: 16 - 20 Years | AB16: Client Relationship Management | AC16: Close Mentorship Event for Masego Basupang with Phetso Ntsowe Create Mentorship Event for Masego Basupang with Phetso Ntsowe | AD16: 45173 | AE16: 45565 | AF16: Mentee Withdrawal - Availability
A17: 2815966 | B17: Kelebogile Disang | C17: Career guidance. Better integration into a team/business unit. Deal with diversity and inclusion challenges. | D17: Career Mentor | E17: Full Time Employee | G17: Female | H17: 40 - 49 | I17: FNB Botswana Commercial (Valentine Harward) | J17: Botswana | K17: FNB | L17: 5010160140 FNB Botswana Commercial Sales P100M+ | M17: Relationship Manager | N17: >20 Years | O17: Client Relationship Management | P17: 5598613 | Q17: Kaone Malete | R17: Full Time Employee | S17: African (Botswana) | T17: Female | U17: 20 - 29 | V17: FNB Botswana Channels (Lorato Mothibi) | W17: Botswana | X17: FNB | Y17: 5010401300 FNB Botswana Mochudi Branch | Z17: Sales and Service Consultant | AA17: <1 Year | AB17: Direct Sales | AC17: Create Mentorship Event for Kaone Malete with Kelebogile Disang | AD17: 45166
A18: 3246388 | B18: Phetso Ntsowe | D18: Career Mentor | E18: Full Time Employee | G18: Female | H18: 40 - 49 | I18: FNB Botswana Retail Banking (Boniface Seane) | J18: Botswana | K18: FNB | L18: 5010292200 FNB Botswana Channels Head Office | M18: Risk Manager | N18: 16 - 20 Years | O18: Operational Risk | P18: 4972279 | Q18: Prince Mopipi (Terminated) | T18: Male | U18: 30 - 39 | W18: Botswana | AA18: 3 - 5 Years | AC18: Close Mentorship Event for Prince Mopipi (Terminated) with Phetso Ntsowe Create Mentorship Event for Prince Mopipi (Terminated) with Phetso Ntsowe | AD18: 45170 | AE18: 45351 | AF18: Mentee Resigned
A19: 3246388 | B19: Phetso Ntsowe | D19: Leadership Mentor | E19: Full Time Employee | G19: Female | H19: 40 - 49 | I19: FNB Botswana Retail Banking (Boniface Seane) | J19: Botswana | K19: FNB | L19: 5010292200 FNB Botswana Channels Head Office | M19: Risk Manager | N19: 16 - 20 Years | O19: Operational Risk | P19: 3243990 | Q19: Gaongalelwe Ikaneng | R19: Full Time Employee | T19: Female | U19: 40 - 49 | V19: FNB Botswana Channels (Kgotso Morei) | W19: Botswana | X19: FNB | Y19: 5010167100 FNB Botswana Main Branch | Z19: Multi Skilled Consultant | AA19: 16 - 20 Years | AB19: Client Experience and Value Management | AC19: Close Mentorship Event for Gaongalelwe Ikaneng with Phetso Ntsowe Create Mentorship Event for Gaongalelwe Ikaneng with Phetso Ntsowe | AD19: 45170 | AE19: 45351 | AF19: Mentee Withdrawal - Availability
A20: 3246388 | B20: Phetso Ntsowe | D20: Career Mentor | E20: Full Time Employee | G20: Female | H20: 40 - 49 | I20: FNB Botswana Retail Banking (Boniface Seane) | J20: Botswana | K20: FNB | L20: 5010292200 FNB Botswana Channels Head Office | M20: Risk Manager | N20: 16 - 20 Years | O20: Operational Risk | P20: 5367891 | Q20: Tebogo Sebobi | R20: Full Time Employee | T20: Male | U20: 30 - 39 | V20: FNB Botswana Channels (Kgomotso Wetshootsile) | W20: Botswana | X20: FNB | Y20: 5010167100 FNB Botswana Main Branch | Z20: Sales Consultant | AA20: 3 - 5 Years | AB20: Direct Sales | AC20: Close Mentorship Event for Tebogo Sebobi with Phetso Ntsowe Create Mentorship Event for Tebogo Sebobi with Phetso Ntsowe | AD20: 45170 | AE20: 45351 | AF20: Mentee Withdrawal - Availability
A21: 3246388 | B21: Phetso Ntsowe | D21: Leadership Mentor | E21: Full Time Employee | G21: Female | H21: 40 - 49 | I21: FNB Botswana Retail Banking (Boniface Seane) | J21: Botswana | K21: FNB | L21: 5010292200 FNB Botswana Channels Head Office | M21: Risk Manager | N21: 16 - 20 Years | O21: Operational Risk | P21: 3505766 | Q21: Amongie Kewakae | R21: Full Time Employee | T21: Female | U21: 40 - 49 | V21: FNB Botswana Channels (Kgomotso Wetshootsile) | W21: Botswana | X21: FNB | Y21: 5010167100 FNB Botswana Main Branch | Z21: Service Consultant | AA21: 16 - 20 Years | AB21: Client Experience and Value Management | AC21: Close Mentorship Event for Amongie Kewakae with Phetso Ntsowe Create Mentorship Event for Amongie Kewakae with Phetso Ntsowe | AD21: 45170 | AE21: 45351 | AF21: Mentee Withdrawal - Availability
A22: 3330370 | B22: Likenkeng Lylian Morojele | C22: I would like to learn more leadership skills in branches. | D22: Leadership Mentor | E22: Full Time Employee | F22: African (Lesotho) | G22: Female | H22: 30 - 39 | I22: FNB Lesotho (Fusi Sefatsane) | J22: Lesotho | K22: FNB | L22: 51800001851 FNB Lesotho Kingway Branch | M22: Branch Manager | N22: 16 - 20 Years | O22: Client Experience and Value Management | P22: 3869865 | Q22: Mapule Mosiuoa | R22: Full Time Employee | S22: African (Lesotho) | T22: Female | U22: 30 - 39 | V22: FNB Lesotho (Mamahao Andronicah Makhoa) | W22: Lesotho | X22: FNB | Y22: 51800002929 FNB Lesotho Retail | Z22: Schemes Coordinator | AA22: 11 -15 Years | AB22: Direct Sales | AC22: Create Mentorship Event for Mapule Mosiuoa with Likenkeng Lylian Morojele | AD22: 45170 | AE22: 45566
A23: 4946073 | B23: Patrick Bontsibokae | C23: Career guidance Broaden organizational knowledge Innovation | D23: Career Mentor | E23: Full Time Employee | F23: African (Botswana) | G23: Male | H23: 30 - 39 | I23: FNB Botswana Commercial (Tiro Kgasa) | J23: Botswana | K23: FNB | L23: 5010160150 FNB Botswana Commercial SME Banking | M23: Relationship Manager | N23: <1 Year | O23: Client Relationship Management | P23: 5598613 | Q23: Kaone Malete | R23: Full Time Employee | S23: African (Botswana) | T23: Female | U23: 20 - 29 | V23: FNB Botswana Channels (Lorato Mothibi) | W23: Botswana | X23: FNB | Y23: 5010401300 FNB Botswana Mochudi Branch | Z23: Sales and Service Consultant | AA23: <1 Year | AB23: Direct Sales | AC23: Create Mentorship Event for Kaone Malete with Patrick Bontsibokae | AD23: 45175 | AE23: 45175
A24: 4778561 | B24: Mike Nyimbili | D24: Leadership Mentor | E24: Full Time Employee | G24: Male | H24: 30 - 39 | I24: FNB Zambia Retail Segment (Njavwa Nakapizye) | J24: Zambia | K24: FNB | L24: 55300003645 FNB Zambia Kasama Branch | M24: Branch Manager | N24: 11 -15 Years | O24: Client Experience and Value Management | P24: 5173353 | Q24: Miyoba Moonga (Terminated) | T24: Female | U24: 30 - 39 | W24: Zambia | AA24: 3 - 5 Years | AC24: Create Mentorship Event for Miyoba Moonga (Terminated) with Mike Nyimbili | AD24: 45236 | AE24: 45249
A25: 3511480 | B25: Kagiso Tlhase (Terminated) | C25: TO LEARN. | D25: Career Mentor | F25: African (Botswana) | G25: Male | H25: 50 - 59 | J25: Botswana | N25: 11 -15 Years | P25: 5595541 | Q25: LILLIAN K EZEKIEL | R25: Fixed Term Contractor | S25: African (Botswana) | T25: Female | U25: 30 - 39 | V25: FNB Botswana Executive Suite (Onkarabile Kono) | W25: Botswana | X25: FNB | Y25: 5010160800 FNB Botswana Retail Operations | Z25: Administration Assistant | AA25: 3 - 5 Years | AB25: Administration | AC25: Create Mentorship Event for LILLIAN K EZEKIEL with Kagiso Tlhase (Terminated) | AD25: 44937 | AE25: 44937
A26: 5084725 | B26: Manuel Motabatshindi | C26: Transition to Systems Analyst job | D26: Career Mentor | E26: Full Time Employee | F26: African (South Africa) | G26: Male | H26: 30 - 39 | I26: CDO Kernel Integrations (Rudzani Nemusombori) | J26: South Africa | K26: FNB | L26: 79000005315 CDO Kernel Integrations | M26: Systems Analyst | N26: 6 - 10 Years | O26: Business/Systems Analysis | P26: 5309697 | Q26: Sifisosakhe Dube | R26: Full Time Employee | S26: African (South Africa) | T26: Male | U26: 30 - 39 | V26: FNB Private Banking and Advisory (Kurt Schurbohm) | W26: South Africa | X26: FNB | Y26: 34100007232 PB&A Service Suite Advisor Engagement | Z26: Private Service Advisor | AA26: 6 - 10 Years | AB26: Client Relationship Management | AC26: Close Mentorship Event for Sifisosakhe Dube with Manuel Motabatshindi Create Mentorship Event for Sifisosakhe Dube with Manuel Motabatshindi | AD26: 44935 | AE26: 45443 | AF26: Mentoring Needs Fulfilled
A27: 7552793 | B27: Theo Ngoma | C27: To fast-track career progression. To improve stakeholder engagement To assist in peer coaching and skills transfer. To align career path and skills training, learning and development. | D27: Career Mentor | E27: Full Time Employee | F27: African (South Africa) | G27: Female | H27: 30 - 39 | I27: CDO Infrastructure and Security Services (Ntswaki Lecage) | J27: South Africa | K27: FNB | L27: 20700005266 CDO Infrastructure and Security Services Command Centre | M27: Enterprise Systems Manager | N27: 3 - 5 Years | O27: System Design and Administration | P27: 5238730 | Q27: Tebogo Moorosi (Terminated) | S27: African (South Africa) | T27: Male | U27: 30 - 39 | W27: South Africa | AA27: 3 - 5 Years | AC27: Create Mentorship Event for Tebogo Moorosi (Terminated) with Theo Ngoma | AD27: 45047 | AE27: 45412
A28: 4942027 | B28: Shantal Reddy | C28: Programme duration is 7 months from Aug – Feb 24 (considering Dec/Jan holidays) Mentees are expected to meet with their mentors at least once a month. Also, an additional 1 day “leave no action” a month aimed at job shadowing virtually or face to face. Mentees are expected to take lead and ensure that sessions are booked on time and alternatives are taken if need be. Mentees are expected let their managers know of their whereabouts during the period where they would be job shadowing or attending masterclasses Kindly sign the NDA and the Agreement attached to the email and send back to me ( Agreement needs your mentor to sign as well so you can get that back to me once you have your introduction session.) Please use the Development Plan to keep track of all the activities and learning you will be doing with your mentor. | D28: Career Mentor | E28: Full Time Employee | F28: Indian (South Africa) | G28: Female | H28: 40 - 49 | I28: FNB Retail COO (Tara Cabion) | J28: South Africa | K28: FNB | L28: 69000006171 FNB Retail Enterprise Project Management Office | M28: Programme Manager | N28: 6 - 10 Years | O28: Programme and Project Management | P28: 4860098 | Q28: Stephanie Bezuidenhout | R28: Full Time Employee | S28: Coloured (South Africa) | T28: Female | U28: 30 - 39 | V28: REMS Real Estate Management Services (Hanifah Khan) | W28: South Africa | X28: FNB | Y28: 22300008588 REMS Property | Z28: Property Administrator | AA28: 11 -15 Years | AB28: Administration | AC28: Create Mentorship Event for Stephanie Bezuidenhout with Shantal Reddy | AD28: 45156 | AE28: 45351
A29: 5266106 | B29: Alison Felix-Lodewyk | C29: Career guidance Manage a career transition. Better integration into a team/business unit | D29: Career Mentor | E29: Full Time Employee | F29: Coloured (South Africa) | G29: Female | H29: 50 - 59 | I29: FNB Personal Human Capital (Shalini John) | J29: South Africa | K29: FNB | L29: 84900003961 FNB ConnectMe EXCO | M29: Human Capital Manager | N29: 6 - 10 Years | O29: Business Human Capital | P29: 5183855 | Q29: Chizoba Mkhwanazi | R29: Full Time Employee | S29: African (South Africa) | T29: Female | U29: 20 - 29 | V29: DirectAxis (Adiela April) | W29: South Africa | X29: FNB | Y29: 99700015134 DA IT Development | Z29: Test Analyst | AA29: 6 - 10 Years | AB29: IT Testing | AC29: Create Mentorship Event for Chizoba Mkhwanazi with Alison Felix-Lodewyk | AD29: 44971 | AE29: 45639
A30: 2285681 | B30: Eddie Roodt | D30: Transition Mentor | E30: Full Time Employee | F30: White (South Africa) | G30: Male | H30: 50 - 59 | I30: FNB International SA (Tsholofelo Mosito) | J30: South Africa | K30: FNB | L30: 83200009889 FNB International SA Learning and Development | M30: Learning Consultant | N30: >20 Years | O30: Experience Architecting | P30: 5516307 | Q30: Mahlori Chauke (Terminated) | S30: African (South Africa) | T30: Male | U30: 30 - 39 | W30: South Africa | AA30: 1 Year | AC30: Create Mentorship Event for Mahlori Chauke (Terminated) with Eddie Roodt | AD30: 44855
A31: 5467845 | B31: Emmanuel Tsiame (Terminated) | D31: Career Mentor | F31: African (South Africa) | G31: Male | H31: 30 - 39 | J31: South Africa | N31: 2 Years | P31: 5573874 | Q31: Refilwe Leburu | R31: Full Time Employee | S31: African (South Africa) | T31: Female | U31: 30 - 39 | V31: FNB Private Banking and Advisory (Caswill Koert) | W31: South Africa | X31: FNB | Y31: 34100007232 PB&A Service Suite Advisor Engagement | Z31: Private Service Advisor | AA31: 3 - 5 Years | AB31: Client Relationship Management | AC31: Create Mentorship Event for Refilwe Leburu with Emmanuel Tsiame (Terminated) | AD31: 45063
A32: 2053527 | B32: Adnaan Rayned | D32: Career Mentor | E32: Full Time Employee | F32: Coloured (South Africa) | G32: Male | H32: 50 - 59 | I32: FNB Commercial Sales Cape (Stephan Claassen) | J32: South Africa | K32: FNB | L32: 34300005001 FNB Commercial Growth Cape Head Office | M32: Regional Head | N32: >20 Years | O32: Sales Management | P32: 5114713 | Q32: Yusuf Ahmed | R32: Full Time Employee | S32: Indian (South Africa) | T32: Male | U32: 30 - 39 | V32: FNB Commercial Projects and Operations (Gavilan Barnes) | W32: South Africa | X32: FNB | Y32: 34200005337 FNB Commercial Security Access Management | Z32: Information Security Administrator | AA32: 1 Year | AB32: IT Security | AC32: Create Mentorship Event for Yusuf Ahmed with Adnaan Rayned | AD32: 45264
A33: 5478960 | B33: Henry Lesar | D33: Career Mentor | E33: Full Time Employee | F33: Coloured (South Africa) | G33: Male | H33: 40 - 49 | I33: CDO Kernel Customer IT (Craig Coombs) | J33: South Africa | K33: FNB | L33: 79000005746 CDO Kernel CIS | M33: Application Development Manager | N33: 3 - 5 Years | O33: IT Development | P33: 5498783 | Q33: Thaveshni Govender | R33: Full Time Employee | S33: Indian (South Africa) | T33: Female | U33: 30 - 39 | V33: CDO Kernel iNterfaceX (Chris Bolle) | W33: South Africa | X33: FNB | Y33: 21800001994 CDO Kernel iNterfaceX Tech App and Mobile Dev App | Z33: Developer | AA33: 3 - 5 Years | AB33: IT Development | AC33: Create Mentorship Event for Thaveshni Govender with Henry Lesar | AD33: 44986
A34: 2404028 | B34: Debbie Maloney | C34: Growth and guidance | D34: Career Mentor | E34: Full Time Employee | F34: White (South Africa) | G34: Female | H34: 50 - 59 | I34: FNB Points of Presence (Edmar Topkin) | J34: South Africa | K34: FNB | L34: 771027100 FNB POP Branch Delivery Koffiefontein | M34: Associate | N34: >20 Years | O34: Client Relationship Management | P34: 4793854 | Q34: Makoae Lawrence Mothibe (Terminated) | S34: African (Lesotho) | T34: Male | U34: 50 - 59 | W34: Lesotho | AA34: 6 - 10 Years | AC34: Create Mentorship Event for Makoae Lawrence Mothibe (Terminated) with Debbie Maloney | AD34: 45260 | AE34: 45535
A35: 2010879 | B35: Dave Aitken (Terminated) | D35: Career Mentor | F35: White (South Africa) | G35: Male | H35: 50 - 59 | J35: South Africa | N35: >20 Years | P35: 2627388 | Q35: Fred Du Plessis | R35: Full Time Employee | S35: White (South Africa) | T35: Male | U35: 40 - 49 | V35: FNB Commercial Sales Gauteng North (Andile Ncoyini) | W35: South Africa | X35: FNB | Y35: 34200006503 FNB Commercial Sales Gauteng Midrand 10 to 60M | Z35: Sales Head | AA35: >20 Years | AB35: Direct Sales | AC35: Create Mentorship Event for Fred Du Plessis with Dave Aitken (Terminated) | AD35: 45108 | AE35: 45473
A36: 4610016 | B36: Gareth Kin | C36: Gareth is assisting Ayanda with Career Development | D36: Career Mentor | E36: Full Time Employee | F36: Coloured (South Africa) | G36: Male | H36: 40 - 49 | I36: FNB Private Segment (Philani Phakamani Potwana) | J36: South Africa | K36: FNB | L36: 41200007842 FNB Private Core Banking Exco | M36: Product Head | N36: 16 - 20 Years | O36: Product Management | P36: 5522633 | Q36: Ayanda Dubazana | R36: Full Time Employee | S36: African (South Africa) | T36: Female | U36: 30 - 39 | V36: FNB Retail Marketing (Sifiso Mahlangu) | W36: South Africa | X36: FNB | Y36: 85500006598 FNB Retail Marketing | Z36: Marketing Portfolio Manager | AA36: 3 - 5 Years | AB36: Marketing, Advertising and Media (incl. digital) | AC36: Create Mentorship Event for Ayanda Dubazana with Gareth Kin | AD36: 45108 | AE36: 45474
A37: 4792718 | B37: Grant Ravno (Terminated) | D37: Technical Mentor | F37: White (South Africa) | G37: Male | H37: 30 - 39 | J37: South Africa | N37: 11 -15 Years | P37: 4765745 | Q37: Tsholofelo Kgwele (Terminated) | S37: African (South Africa) | T37: Male | U37: 30 - 39 | W37: South Africa | AA37: 11 -15 Years | AC37: Create Mentorship Event for Tsholofelo Kgwele (Terminated) with Grant Ravno (Terminated) | AD37: 45231 | AE37: 45443
A38: 3486850 | B38: Ilyas Patel | C38: Shahida is looking for exposure in total reward | D38: Career Mentor | E38: Full Time Employee | F38: Indian (South Africa) | G38: Male | H38: 40 - 49 | I38: Group Human Capital (Zama Lamla) | J38: South Africa | K38: FirstRand Corporate Centre | L38: 20200003706 Group Reward | M38: Reward Head FCC and Group Shares | N38: 16 - 20 Years | O38: Experience Architecting | P38: 3614263 | Q38: Shahida Begg | R38: Full Time Employee | S38: Coloured (South Africa) | T38: Female | U38: 30 - 39 | V38: FNB Points of Presence (Charlene Calleja) | W38: South Africa | X38: FNB | Y38: 7710644300 FNB POP HC Operations and Talent Management | Z38: Operations Manager | AA38: 11 -15 Years | AB38: Operations | AC38: Create Mentorship Event for Shahida Begg with Ilyas Patel Edit Mentorship Event for Shahida Begg with Ilyas Patel | AD38: 45244 | AE38: 45596
A39: 3355268 | B39: Josh Minyuku (Terminated) | C39: Leadership in Branch programme | D39: Leadership Mentor | F39: African (South Africa) | G39: Male | H39: 40 - 49 | J39: South Africa | N39: 16 - 20 Years | P39: 4788540 | Q39: Kgaugelo Kulube | R39: Full Time Employee | S39: African (South Africa) | T39: Female | U39: 30 - 39 | V39: FNB Points of Presence (Abednigo Chauke) | W39: South Africa | X39: FNB | Y39: 7710693500 FNB POP Branch Delivery Zebediela Plaza | Z39: Branch Controller | AA39: 11 -15 Years | AB39: Administration | AC39: Create Mentorship Event for Kgaugelo Kulube with Josh Minyuku (Terminated) | AD39: 45209 | AE39: 45412
A40: 5235049 | B40: Rialivhuwa Mudau | C40: The purpose of the mentorship is to Learn about different careers and fields. Provide guidance and support during difficult times, and in narrowing what to study to archive my career goals. Clarify and narrow down my unique strengths and journey | D40: Career Mentor | E40: Full Time Employee | F40: African (South Africa) | G40: Female | H40: 30 - 39 | I40: FNB Personal Segment Advisory and Suites (Devesh Naidoo) | J40: South Africa | K40: FNB | L40: 97200005382 PSAS Stratco | M40: Risk Head | N40: 6 - 10 Years | O40: Operational Risk | P40: 5246628 | Q40: Anelisa Singanzi | R40: Full Time Employee | S40: African (South Africa) | T40: Female | U40: 40 - 49 | V40: FNB Loans (Prolene Louw) | W40: South Africa | X40: FNB | Y40: 79100003305 FNB Consumer Loans Internal Collections | Z40: Collections Advisor | AA40: 11 -15 Years | AB40: Collections and Recoveries | AC40: Create Mentorship Event for Anelisa Singanzi with Rialivhuwa Mudau | AD40: 44593 | AE40: 45833
...

Sheet Mentor Pool
A1: Total in Workday | B1: =COUNTA('Paste - Mentors'!B4:B5000) -> 926 | D1: Available | E1: =COUNTIF(G4:G948,"Available") -> 805
C2: =IFERROR(VLOOKUP(E1,'Paste - Mentors'!$A:$B,2,0),"")
A3: Employee ID | B3: Mentor Name | C3: Mentor Type(s) | D3: Franchise | E3: Country | F3: Active Mentees (Workday) | G3: Capacity Status | H3: In Programme? (auto-check)
A4: ='Paste - Mentors'!A4 -> 5183472 | B4: =IFERROR(VLOOKUP(A4,'Paste - Mentors'!$A:$B,2,0),"") -> Gerald Maunda | C4: =IFERROR(VLOOKUP(A4,'Paste - Mentors'!$A:$D,4,0),"") -> Career Mentor | D4: =IFERROR(VLOOKUP(A4,'Paste - Mentors'!$A:$F,6,0),"") -> FNB | E4: =IFERROR(VLOOKUP(A4,'Paste - Mentors'!$A:$E,5,0),"") -> Zambia | F4: =IF(A4="","",COUNTIFS('Paste - Relationships'!$A:$A,A4,'Paste - Relationships'!$AE:$AE,"")) -> 0 | G4: =IF(A4="","",IF(F4>=3,"At Capacity",IF(F4=0,"Available","Has Capacity"))) -> Available | H4: =IF(A4="","",IF(COUNTIF('Programme Mentors'!$A:$A,A4)>0,"Enrolled","—")) -> —
A5: ='Paste - Mentors'!A5 -> 5495989 | B5: =IFERROR(VLOOKUP(A5,'Paste - Mentors'!$A:$B,2,0),"") -> Bonolo Molebatsi | C5: =IFERROR(VLOOKUP(A5,'Paste - Mentors'!$A:$D,4,0),"") -> Career Mentor | D5: =IFERROR(VLOOKUP(A5,'Paste - Mentors'!$A:$F,6,0),"") -> FNB | E5: =IFERROR(VLOOKUP(A5,'Paste - Mentors'!$A:$E,5,0),"") -> Botswana | F5: =IF(A5="","",COUNTIFS('Paste - Relationships'!$A:$A,A5,'Paste - Relationships'!$AE:$AE,"")) -> 1 | G5: =IF(A5="","",IF(F5>=3,"At Capacity",IF(F5=0,"Available","Has Capacity"))) -> Has Capacity | H5: =IF(A5="","",IF(COUNTIF('Programme Mentors'!$A:$A,A5)>0,"Enrolled","—")) -> —
A6: ='Paste - Mentors'!A6 -> 5009642 | B6: =IFERROR(VLOOKUP(A6,'Paste - Mentors'!$A:$B,2,0),"") -> Otisitswe Faith Rathedi | C6: =IFERROR(VLOOKUP(A6,'Paste - Mentors'!$A:$D,4,0),"") -> Career Mentor Leadership Mentor | D6: =IFERROR(VLOOKUP(A6,'Paste - Mentors'!$A:$F,6,0),"") -> FNB | E6: =IFERROR(VLOOKUP(A6,'Paste - Mentors'!$A:$E,5,0),"") -> Botswana | F6: =IF(A6="","",COUNTIFS('Paste - Relationships'!$A:$A,A6,'Paste - Relationships'!$AE:$AE,"")) -> 1 | G6: =IF(A6="","",IF(F6>=3,"At Capacity",IF(F6=0,"Available","Has Capacity"))) -> Has Capacity | H6: =IF(A6="","",IF(COUNTIF('Programme Mentors'!$A:$A,A6)>0,"Enrolled","—")) -> —
A7: ='Paste - Mentors'!A7 -> 5109140 | B7: =IFERROR(VLOOKUP(A7,'Paste - Mentors'!$A:$B,2,0),"") -> Bydon Longwe | C7: =IFERROR(VLOOKUP(A7,'Paste - Mentors'!$A:$D,4,0),"") -> Career Mentor | D7: =IFERROR(VLOOKUP(A7,'Paste - Mentors'!$A:$F,6,0),"") -> FNB | E7: =IFERROR(VLOOKUP(A7,'Paste - Mentors'!$A:$E,5,0),"") -> South Africa | F7: =IF(A7="","",COUNTIFS('Paste - Relationships'!$A:$A,A7,'Paste - Relationships'!$AE:$AE,"")) -> 1 | G7: =IF(A7="","",IF(F7>=3,"At Capacity",IF(F7=0,"Available","Has Capacity"))) -> Has Capacity | H7: =IF(A7="","",IF(COUNTIF('Programme Mentors'!$A:$A,A7)>0,"Enrolled","—")) -> —
A8: ='Paste - Mentors'!A8 -> 4946073 | B8: =IFERROR(VLOOKUP(A8,'Paste - Mentors'!$A:$B,2,0),"") -> Patrick Bontsibokae | C8: =IFERROR(VLOOKUP(A8,'Paste - Mentors'!$A:$D,4,0),"") -> Career Mentor | D8: =IFERROR(VLOOKUP(A8,'Paste - Mentors'!$A:$F,6,0),"") -> FNB | E8: =IFERROR(VLOOKUP(A8,'Paste - Mentors'!$A:$E,5,0),"") -> Botswana | F8: =IF(A8="","",COUNTIFS('Paste - Relationships'!$A:$A,A8,'Paste - Relationships'!$AE:$AE,"")) -> 0 | G8: =IF(A8="","",IF(F8>=3,"At Capacity",IF(F8=0,"Available","Has Capacity"))) -> Available | H8: =IF(A8="","",IF(COUNTIF('Programme Mentors'!$A:$A,A8)>0,"Enrolled","—")) -> —
A9: ='Paste - Mentors'!A9 -> 4997751 | B9: =IFERROR(VLOOKUP(A9,'Paste - Mentors'!$A:$B,2,0),"") -> Caroline Kepaletswe | C9: =IFERROR(VLOOKUP(A9,'Paste - Mentors'!$A:$D,4,0),"") -> Career Mentor | D9: =IFERROR(VLOOKUP(A9,'Paste - Mentors'!$A:$F,6,0),"") -> FNB | E9: =IFERROR(VLOOKUP(A9,'Paste - Mentors'!$A:$E,5,0),"") -> Botswana | F9: =IF(A9="","",COUNTIFS('Paste - Relationships'!$A:$A,A9,'Paste - Relationships'!$AE:$AE,"")) -> 1 | G9: =IF(A9="","",IF(F9>=3,"At Capacity",IF(F9=0,"Available","Has Capacity"))) -> Has Capacity | H9: =IF(A9="","",IF(COUNTIF('Programme Mentors'!$A:$A,A9)>0,"Enrolled","—")) -> —
A10: ='Paste - Mentors'!A10 -> 4714849 | B10: =IFERROR(VLOOKUP(A10,'Paste - Mentors'!$A:$B,2,0),"") -> Chapita Mbuzi | C10: =IFERROR(VLOOKUP(A10,'Paste - Mentors'!$A:$D,4,0),"") -> Career Mentor | D10: =IFERROR(VLOOKUP(A10,'Paste - Mentors'!$A:$F,6,0),"") -> FNB | E10: =IFERROR(VLOOKUP(A10,'Paste - Mentors'!$A:$E,5,0),"") -> Zambia | F10: =IF(A10="","",COUNTIFS('Paste - Relationships'!$A:$A,A10,'Paste - Relationships'!$AE:$AE,"")) -> 0 | G10: =IF(A10="","",IF(F10>=3,"At Capacity",IF(F10=0,"Available","Has Capacity"))) -> Available | H10: =IF(A10="","",IF(COUNTIF('Programme Mentors'!$A:$A,A10)>0,"Enrolled","—")) -> —
A11: ='Paste - Mentors'!A11 -> 3872521 | B11: =IFERROR(VLOOKUP(A11,'Paste - Mentors'!$A:$B,2,0),"") -> Wiza Phiri | C11: =IFERROR(VLOOKUP(A11,'Paste - Mentors'!$A:$D,4,0),"") -> Career Mentor | D11: =IFERROR(VLOOKUP(A11,'Paste - Mentors'!$A:$F,6,0),"") -> FNB | E11: =IFERROR(VLOOKUP(A11,'Paste - Mentors'!$A:$E,5,0),"") -> Zambia | F11: =IF(A11="","",COUNTIFS('Paste - Relationships'!$A:$A,A11,'Paste - Relationships'!$AE:$AE,"")) -> 0 | G11: =IF(A11="","",IF(F11>=3,"At Capacity",IF(F11=0,"Available","Has Capacity"))) -> Available | H11: =IF(A11="","",IF(COUNTIF('Programme Mentors'!$A:$A,A11)>0,"Enrolled","—")) -> —
A12: ='Paste - Mentors'!A12 -> 4930088 | B12: =IFERROR(VLOOKUP(A12,'Paste - Mentors'!$A:$B,2,0),"") -> Retselisitsoe Sylvia Khet'semane | C12: =IFERROR(VLOOKUP(A12,'Paste - Mentors'!$A:$D,4,0),"") -> Career Mentor | D12: =IFERROR(VLOOKUP(A12,'Paste - Mentors'!$A:$F,6,0),"") -> FNB | E12: =IFERROR(VLOOKUP(A12,'Paste - Mentors'!$A:$E,5,0),"") -> Lesotho | F12: =IF(A12="","",COUNTIFS('Paste - Relationships'!$A:$A,A12,'Paste - Relationships'!$AE:$AE,"")) -> 0 | G12: =IF(A12="","",IF(F12>=3,"At Capacity",IF(F12=0,"Available","Has Capacity"))) -> Available | H12: =IF(A12="","",IF(COUNTIF('Programme Mentors'!$A:$A,A12)>0,"Enrolled","—")) -> —
A13: ='Paste - Mentors'!A13 -> 4989171 | B13: =IFERROR(VLOOKUP(A13,'Paste - Mentors'!$A:$B,2,0),"") -> Borethe Mogwe | C13: =IFERROR(VLOOKUP(A13,'Paste - Mentors'!$A:$D,4,0),"") -> Career Mentor | D13: =IFERROR(VLOOKUP(A13,'Paste - Mentors'!$A:$F,6,0),"") -> FNB | E13: =IFERROR(VLOOKUP(A13,'Paste - Mentors'!$A:$E,5,0),"") -> Botswana | F13: =IF(A13="","",COUNTIFS('Paste - Relationships'!$A:$A,A13,'Paste - Relationships'!$AE:$AE,"")) -> 2 | G13: =IF(A13="","",IF(F13>=3,"At Capacity",IF(F13=0,"Available","Has Capacity"))) -> Has Capacity | H13: =IF(A13="","",IF(COUNTIF('Programme Mentors'!$A:$A,A13)>0,"Enrolled","—")) -> —
A14: ='Paste - Mentors'!A14 -> 4804473 | B14: =IFERROR(VLOOKUP(A14,'Paste - Mentors'!$A:$B,2,0),"") -> Gofaone Mokalake | C14: =IFERROR(VLOOKUP(A14,'Paste - Mentors'!$A:$D,4,0),"") -> Career Mentor Leadership Mentor | D14: =IFERROR(VLOOKUP(A14,'Paste - Mentors'!$A:$F,6,0),"") -> FNB | E14: =IFERROR(VLOOKUP(A14,'Paste - Mentors'!$A:$E,5,0),"") -> Botswana | F14: =IF(A14="","",COUNTIFS('Paste - Relationships'!$A:$A,A14,'Paste - Relationships'!$AE:$AE,"")) -> 0 | G14: =IF(A14="","",IF(F14>=3,"At Capacity",IF(F14=0,"Available","Has Capacity"))) -> Available | H14: =IF(A14="","",IF(COUNTIF('Programme Mentors'!$A:$A,A14)>0,"Enrolled","—")) -> —
A15: ='Paste - Mentors'!A15 -> 4868455 | B15: =IFERROR(VLOOKUP(A15,'Paste - Mentors'!$A:$B,2,0),"") -> Tshepo Sentle | C15: =IFERROR(VLOOKUP(A15,'Paste - Mentors'!$A:$D,4,0),"") -> Career Mentor | D15: =IFERROR(VLOOKUP(A15,'Paste - Mentors'!$A:$F,6,0),"") -> FNB | E15: =IFERROR(VLOOKUP(A15,'Paste - Mentors'!$A:$E,5,0),"") -> Botswana | F15: =IF(A15="","",COUNTIFS('Paste - Relationships'!$A:$A,A15,'Paste - Relationships'!$AE:$AE,"")) -> 0 | G15: =IF(A15="","",IF(F15>=3,"At Capacity",IF(F15=0,"Available","Has Capacity"))) -> Available | H15: =IF(A15="","",IF(COUNTIF('Programme Mentors'!$A:$A,A15)>0,"Enrolled","—")) -> —
... A947: ='Paste - Mentors'!A947 -> 0 | B947: =IFERROR(VLOOKUP(A947,'Paste - Mentors'!$A:$B,2,0),"") | C947: =IFERROR(VLOOKUP(A947,'Paste - Mentors'!$A:$D,4,0),"") | D947: =IFERROR(VLOOKUP(A947,'Paste - Mentors'!$A:$F,6,0),"") | E947: =IFERROR(VLOOKUP(A947,'Paste - Mentors'!$A:$E,5,0),"") | F947: =IF(A947="","",COUNTIFS('Paste - Relationships'!$A:$A,A947,'Paste - Relationships'!$AE:$AE,"")) -> 0 | G947: =IF(A947="","",IF(F947>=3,"At Capacity",IF(F947=0,"Available","Has Capacity"))) -> Available | H947: =IF(A947="","",IF(COUNTIF('Programme Mentors'!$A:$A,A947)>0,"Enrolled","—")) -> —

Sheet Programme Mentors
A1: Total Enrolled Mentors | B1: =COUNTA(A4:A298) -> 0 | D1: Not on Workday (Action Req) | E1: =COUNTIF(G4:G298,"Not Found") -> 0
A3: Employee ID | B3: Full Name | C3: Max Mentees (default=3) | D3: Date Added to Programme | E3: Supervisory Org | F3: Job Title | G3: Workday Status | H3: Current Mentees | I3: Remaining Capacity
B4: =IFERROR(VLOOKUP(A4,'Paste - Mentors'!$A:$B,2,0),"") | E4: =IFERROR(VLOOKUP(A4,'Paste - Mentors'!$A:$G,7,0),"") | F4: =IFERROR(VLOOKUP(A4,'Paste - Mentors'!$A:$K,11,0),"") | G4: =IF(A4="","",IF(COUNTIF('Paste - Mentors'!$A:$A,A4)>0,"Registered","Not Found")) | H4: =IF(A4="","",COUNTIF('Intern Monitoring'!$D$4:$D$203,B4)) | I4: =IF(A4="","",IFERROR(IF(C4="",3,C4)-IF(H4="",0,H4),"-"))
B5: =IFERROR(VLOOKUP(A5,'Paste - Mentors'!$A:$B,2,0),"") | E5: =IFERROR(VLOOKUP(A5,'Paste - Mentors'!$A:$G,7,0),"") | F5: =IFERROR(VLOOKUP(A5,'Paste - Mentors'!$A:$K,11,0),"") | G5: =IF(A5="","",IF(COUNTIF('Paste - Mentors'!$A:$A,A5)>0,"Registered","Not Found")) | H5: =IF(A5="","",COUNTIF('Intern Monitoring'!$D$4:$D$203,B5)) | I5: =IF(A5="","",IFERROR(IF(C5="",3,C5)-IF(H5="",0,H5),"-"))
B6: =IFERROR(VLOOKUP(A6,'Paste - Mentors'!$A:$B,2,0),"") | E6: =IFERROR(VLOOKUP(A6,'Paste - Mentors'!$A:$G,7,0),"") | F6: =IFERROR(VLOOKUP(A6,'Paste - Mentors'!$A:$K,11,0),"") | G6: =IF(A6="","",IF(COUNTIF('Paste - Mentors'!$A:$A,A6)>0,"Registered","Not Found")) | H6: =IF(A6="","",COUNTIF('Intern Monitoring'!$D$4:$D$203,B6)) | I6: =IF(A6="","",IFERROR(IF(C6="",3,C6)-IF(H6="",0,H6),"-"))
B7: =IFERROR(VLOOKUP(A7,'Paste - Mentors'!$A:$B,2,0),"") | E7: =IFERROR(VLOOKUP(A7,'Paste - Mentors'!$A:$G,7,0),"") | F7: =IFERROR(VLOOKUP(A7,'Paste - Mentors'!$A:$K,11,0),"") | G7: =IF(A7="","",IF(COUNTIF('Paste - Mentors'!$A:$A,A7)>0,"Registered","Not Found")) | H7: =IF(A7="","",COUNTIF('Intern Monitoring'!$D$4:$D$203,B7)) | I7: =IF(A7="","",IFERROR(IF(C7="",3,C7)-IF(H7="",0,H7),"-"))
B8: =IFERROR(VLOOKUP(A8,'Paste - Mentors'!$A:$B,2,0),"") | E8: =IFERROR(VLOOKUP(A8,'Paste - Mentors'!$A:$G,7,0),"") | F8: =IFERROR(VLOOKUP(A8,'Paste - Mentors'!$A:$K,11,0),"") | G8: =IF(A8="","",IF(COUNTIF('Paste - Mentors'!$A:$A,A8)>0,"Registered","Not Found")) | H8: =IF(A8="","",COUNTIF('Intern Monitoring'!$D$4:$D$203,B8)) | I8: =IF(A8="","",IFERROR(IF(C8="",3,C8)-IF(H8="",0,H8),"-"))
B9: =IFERROR(VLOOKUP(A9,'Paste - Mentors'!$A:$B,2,0),"") | E9: =IFERROR(VLOOKUP(A9,'Paste - Mentors'!$A:$G,7,0),"") | F9: =IFERROR(VLOOKUP(A9,'Paste - Mentors'!$A:$K,11,0),"") | G9: =IF(A9="","",IF(COUNTIF('Paste - Mentors'!$A:$A,A9)>0,"Registered","Not Found")) | H9: =IF(A9="","",COUNTIF('Intern Monitoring'!$D$4:$D$203,B9)) | I9: =IF(A9="","",IFERROR(IF(C9="",3,C9)-IF(H9="",0,H9),"-"))
B10: =IFERROR(VLOOKUP(A10,'Paste - Mentors'!$A:$B,2,0),"") | E10: =IFERROR(VLOOKUP(A10,'Paste - Mentors'!$A:$G,7,0),"") | F10: =IFERROR(VLOOKUP(A10,'Paste - Mentors'!$A:$K,11,0),"") | G10: =IF(A10="","",IF(COUNTIF('Paste - Mentors'!$A:$A,A10)>0,"Registered","Not Found")) | H10: =IF(A10="","",COUNTIF('Intern Monitoring'!$D$4:$D$203,B10)) | I10: =IF(A10="","",IFERROR(IF(C10="",3,C10)-IF(H10="",0,H10),"-"))
B11: =IFERROR(VLOOKUP(A11,'Paste - Mentors'!$A:$B,2,0),"") | E11: =IFERROR(VLOOKUP(A11,'Paste - Mentors'!$A:$G,7,0),"") | F11: =IFERROR(VLOOKUP(A11,'Paste - Mentors'!$A:$K,11,0),"") | G11: =IF(A11="","",IF(COUNTIF('Paste - Mentors'!$A:$A,A11)>0,"Registered","Not Found")) | H11: =IF(A11="","",COUNTIF('Intern Monitoring'!$D$4:$D$203,B11)) | I11: =IF(A11="","",IFERROR(IF(C11="",3,C11)-IF(H11="",0,H11),"-"))
B12: =IFERROR(VLOOKUP(A12,'Paste - Mentors'!$A:$B,2,0),"") | E12: =IFERROR(VLOOKUP(A12,'Paste - Mentors'!$A:$G,7,0),"") | F12: =IFERROR(VLOOKUP(A12,'Paste - Mentors'!$A:$K,11,0),"") | G12: =IF(A12="","",IF(COUNTIF('Paste - Mentors'!$A:$A,A12)>0,"Registered","Not Found")) | H12: =IF(A12="","",COUNTIF('Intern Monitoring'!$D$4:$D$203,B12)) | I12: =IF(A12="","",IFERROR(IF(C12="",3,C12)-IF(H12="",0,H12),"-"))
