Workbook
Name Assumptions_BonusTable: Assumptions!$B$5:$G$9
Name Assumptions_RatingCat: Assumptions!$E$5:$E$9
Name Assumptions_ScoreMin: Assumptions!$B$5:$B$9
Name RawData_Amount: 'Raw Data'!$J:$J
Name RawData_Comment: 'Raw Data'!$K:$K
Name RawData_Division: 'Raw Data'!$E:$E
Name RawData_EmpNo: 'Raw Data'!$A:$A
Name RawData_OBR: 'Raw Data'!$H:$H
Name RawData_OpsYM: 'Raw Data'!$B:$B
Name RawData_QA: 'Raw Data'!$G:$G
Name RawData_SalesInc: 'Raw Data'!$I:$I
Name RawData_Score: 'Raw Data'!$F:$F
Name RawData_Team: 'Raw Data'!$D:$D
Name RawData_UserName: 'Raw Data'!$C:$C

Sheet OBR vs ARR Calculator
A1: OBR vs ARR Comparison Calculator — Servicing Team (Feb 2025 – Feb 2026)
A2: # | B2: Emp No | C2: Employee Name | D2: Team | E2: Months in Period | F2: Total OBR Received | G2: Projected 12-Month OBR | H2: Avg Monthly OBR | I2: Avg Performance Score | J2: Rating Category | K2: INPUT: ARR Annual Salary (R) | L2: ARR Bonus Amount (R) | M2: Total ARR Package (R) | N2: OBR Shortfall vs ARR | O2: OBR Beats Package? | P2: Projected OBR as % of Salary
A3: 1 | B3: =IFERROR(INDEX(RawData_EmpNo,MATCH(C3,RawData_UserName,0)),"") -> 1004 | C3: RenechiaJoseph | D3: =IFERROR(INDEX(RawData_Team,MATCH(C3,RawData_UserName,0)),"") -> LOC 2 | E3: =COUNTIF(RawData_UserName,C3) -> 12 | F3: =SUMIF(RawData_UserName,C3,RawData_Amount) -> 67600 | G3: =IF(E3=12,F3,H3*12) -> 67600 | H3: =IFERROR(F3/E3,0) -> 5633.3333 | I3: =IFERROR(AVERAGEIF(RawData_UserName,C3,RawData_Score),"") -> 2.5616667 | J3: =IF(I3="",Assumptions!$E$6,VLOOKUP(I3,Assumptions!$B$5:$E$9,4,TRUE())) -> Improvement Required | L3: =IF(K3="","",IF(OR(J3=Assumptions!$E$5,J3=Assumptions!$E$6),VLOOKUP(J3,Assumptions!$E$5:$F$9,2,FALSE()),MAX(VLOOKUP(J3,Assumptions!$E$5:$F$9,2,FALSE()),K3*VLOOKUP(J3,Assumptions!$E$5:$G$9,3,FALSE())))) | M3: =IF(K3="","",K3+L3) | N3: =IF(M3="","",G3-M3) | O3: =IF(M3="","",IF(G3>M3,"YES","NO")) | P3: =IF(K3="","",G3/K3)
A4: 2 | B4: =IFERROR(INDEX(RawData_EmpNo,MATCH(C4,RawData_UserName,0)),"") -> 1006 | C4: BrutersMasindi | D4: =IFERROR(INDEX(RawData_Team,MATCH(C4,RawData_UserName,0)),"") -> LOC 2 | E4: =COUNTIF(RawData_UserName,C4) -> 12 | F4: =SUMIF(RawData_UserName,C4,RawData_Amount) -> 65845 | G4: =IF(E4=12,F4,H4*12) -> 65845 | H4: =IFERROR(F4/E4,0) -> 5487.0833 | I4: =IFERROR(AVERAGEIF(RawData_UserName,C4,RawData_Score),"") -> 4.0025 | J4: =IF(I4="",Assumptions!$E$6,VLOOKUP(I4,Assumptions!$B$5:$E$9,4,TRUE())) -> Exceptional | L4: =IF(K4="","",IF(OR(J4=Assumptions!$E$5,J4=Assumptions!$E$6),VLOOKUP(J4,Assumptions!$E$5:$F$9,2,FALSE()),MAX(VLOOKUP(J4,Assumptions!$E$5:$F$9,2,FALSE()),K4*VLOOKUP(J4,Assumptions!$E$5:$G$9,3,FALSE())))) | M4: =IF(K4="","",K4+L4) | N4: =IF(M4="","",G4-M4) | O4: =IF(M4="","",IF(G4>M4,"YES","NO")) | P4: =IF(K4="","",G4/K4)
A5: 3 | B5: =IFERROR(INDEX(RawData_EmpNo,MATCH(C5,RawData_UserName,0)),"") -> 1001 | C5: DaphneyMmota | D5: =IFERROR(INDEX(RawData_Team,MATCH(C5,RawData_UserName,0)),"") -> LOC 2 | E5: =COUNTIF(RawData_UserName,C5) -> 12 | F5: =SUMIF(RawData_UserName,C5,RawData_Amount) -> 64107.5 | G5: =IF(E5=12,F5,H5*12) -> 64107.5 | H5: =IFERROR(F5/E5,0) -> 5342.2917 | I5: =IFERROR(AVERAGEIF(RawData_UserName,C5,RawData_Score),"") -> 4.0766667 | J5: =IF(I5="",Assumptions!$E$6,VLOOKUP(I5,Assumptions!$B$5:$E$9,4,TRUE())) -> Exceptional | L5: =IF(K5="","",IF(OR(J5=Assumptions!$E$5,J5=Assumptions!$E$6),VLOOKUP(J5,Assumptions!$E$5:$F$9,2,FALSE()),MAX(VLOOKUP(J5,Assumptions!$E$5:$F$9,2,FALSE()),K5*VLOOKUP(J5,Assumptions!$E$5:$G$9,3,FALSE())))) | M5: =IF(K5="","",K5+L5) | N5: =IF(M5="","",G5-M5) | O5: =IF(M5="","",IF(G5>M5,"YES","NO")) | P5: =IF(K5="","",G5/K5)
A6: 4 | B6: =IFERROR(INDEX(RawData_EmpNo,MATCH(C6,RawData_UserName,0)),"") -> 1009 | C6: TishkaGan | D6: =IFERROR(INDEX(RawData_Team,MATCH(C6,RawData_UserName,0)),"") -> LOC 1 | E6: =COUNTIF(RawData_UserName,C6) -> 10 | F6: =SUMIF(RawData_UserName,C6,RawData_Amount) -> 61225 | G6: =IF(E6=12,F6,H6*12) -> 73470 | H6: =IFERROR(F6/E6,0) -> 6122.5 | I6: =IFERROR(AVERAGEIF(RawData_UserName,C6,RawData_Score),"") -> 2.733 | J6: =IF(I6="",Assumptions!$E$6,VLOOKUP(I6,Assumptions!$B$5:$E$9,4,TRUE())) -> Improvement Required | L6: =IF(K6="","",IF(OR(J6=Assumptions!$E$5,J6=Assumptions!$E$6),VLOOKUP(J6,Assumptions!$E$5:$F$9,2,FALSE()),MAX(VLOOKUP(J6,Assumptions!$E$5:$F$9,2,FALSE()),K6*VLOOKUP(J6,Assumptions!$E$5:$G$9,3,FALSE())))) | M6: =IF(K6="","",K6+L6) | N6: =IF(M6="","",G6-M6) | O6: =IF(M6="","",IF(G6>M6,"YES","NO")) | P6: =IF(K6="","",G6/K6)
A7: 5 | B7: =IFERROR(INDEX(RawData_EmpNo,MATCH(C7,RawData_UserName,0)),"") -> 1015 | C7: SinikiweHlatswayo | D7: =IFERROR(INDEX(RawData_Team,MATCH(C7,RawData_UserName,0)),"") -> LOC 2 | E7: =COUNTIF(RawData_UserName,C7) -> 12 | F7: =SUMIF(RawData_UserName,C7,RawData_Amount) -> 57357.14 | G7: =IF(E7=12,F7,H7*12) -> 57357.14 | H7: =IFERROR(F7/E7,0) -> 4779.7617 | I7: =IFERROR(AVERAGEIF(RawData_UserName,C7,RawData_Score),"") -> 4.2358333 | J7: =IF(I7="",Assumptions!$E$6,VLOOKUP(I7,Assumptions!$B$5:$E$9,4,TRUE())) -> Exceptional | L7: =IF(K7="","",IF(OR(J7=Assumptions!$E$5,J7=Assumptions!$E$6),VLOOKUP(J7,Assumptions!$E$5:$F$9,2,FALSE()),MAX(VLOOKUP(J7,Assumptions!$E$5:$F$9,2,FALSE()),K7*VLOOKUP(J7,Assumptions!$E$5:$G$9,3,FALSE())))) | M7: =IF(K7="","",K7+L7) | N7: =IF(M7="","",G7-M7) | O7: =IF(M7="","",IF(G7>M7,"YES","NO")) | P7: =IF(K7="","",G7/K7)
A8: 6 | B8: =IFERROR(INDEX(RawData_EmpNo,MATCH(C8,RawData_UserName,0)),"") -> 1016 | C8: SiveshManikkam | D8: =IFERROR(INDEX(RawData_Team,MATCH(C8,RawData_UserName,0)),"") -> Comp 1 | E8: =COUNTIF(RawData_UserName,C8) -> 10 | F8: =SUMIF(RawData_UserName,C8,RawData_Amount) -> 55000 | G8: =IF(E8=12,F8,H8*12) -> 66000 | H8: =IFERROR(F8/E8,0) -> 5500 | I8: =IFERROR(AVERAGEIF(RawData_UserName,C8,RawData_Score),"") -> 2.629 | J8: =IF(I8="",Assumptions!$E$6,VLOOKUP(I8,Assumptions!$B$5:$E$9,4,TRUE())) -> Improvement Required | L8: =IF(K8="","",IF(OR(J8=Assumptions!$E$5,J8=Assumptions!$E$6),VLOOKUP(J8,Assumptions!$E$5:$F$9,2,FALSE()),MAX(VLOOKUP(J8,Assumptions!$E$5:$F$9,2,FALSE()),K8*VLOOKUP(J8,Assumptions!$E$5:$G$9,3,FALSE())))) | M8: =IF(K8="","",K8+L8) | N8: =IF(M8="","",G8-M8) | O8: =IF(M8="","",IF(G8>M8,"YES","NO")) | P8: =IF(K8="","",G8/K8)
A9: 7 | B9: =IFERROR(INDEX(RawData_EmpNo,MATCH(C9,RawData_UserName,0)),"") -> 1029 | C9: MabelSelesho | D9: =IFERROR(INDEX(RawData_Team,MATCH(C9,RawData_UserName,0)),"") -> LOC 2 | E9: =COUNTIF(RawData_UserName,C9) -> 12 | F9: =SUMIF(RawData_UserName,C9,RawData_Amount) -> 54750 | G9: =IF(E9=12,F9,H9*12) -> 54750 | H9: =IFERROR(F9/E9,0) -> 4562.5 | I9: =IFERROR(AVERAGEIF(RawData_UserName,C9,RawData_Score),"") -> 4.0125 | J9: =IF(I9="",Assumptions!$E$6,VLOOKUP(I9,Assumptions!$B$5:$E$9,4,TRUE())) -> Exceptional | L9: =IF(K9="","",IF(OR(J9=Assumptions!$E$5,J9=Assumptions!$E$6),VLOOKUP(J9,Assumptions!$E$5:$F$9,2,FALSE()),MAX(VLOOKUP(J9,Assumptions!$E$5:$F$9,2,FALSE()),K9*VLOOKUP(J9,Assumptions!$E$5:$G$9,3,FALSE())))) | M9: =IF(K9="","",K9+L9) | N9: =IF(M9="","",G9-M9) | O9: =IF(M9="","",IF(G9>M9,"YES","NO")) | P9: =IF(K9="","",G9/K9)
A10: 8 | B10: =IFERROR(INDEX(RawData_EmpNo,MATCH(C10,RawData_UserName,0)),"") -> 1021 | C10: ChaseMoses | D10: =IFERROR(INDEX(RawData_Team,MATCH(C10,RawData_UserName,0)),"") -> LOC 2 | E10: =COUNTIF(RawData_UserName,C10) -> 12 | F10: =SUMIF(RawData_UserName,C10,RawData_Amount) -> 52991.25 | G10: =IF(E10=12,F10,H10*12) -> 52991.25 | H10: =IFERROR(F10/E10,0) -> 4415.9375 | I10: =IFERROR(AVERAGEIF(RawData_UserName,C10,RawData_Score),"") -> 3.365 | J10: =IF(I10="",Assumptions!$E$6,VLOOKUP(I10,Assumptions!$B$5:$E$9,4,TRUE())) -> Meets Expectation | L10: =IF(K10="","",IF(OR(J10=Assumptions!$E$5,J10=Assumptions!$E$6),VLOOKUP(J10,Assumptions!$E$5:$F$9,2,FALSE()),MAX(VLOOKUP(J10,Assumptions!$E$5:$F$9,2,FALSE()),K10*VLOOKUP(J10,Assumptions!$E$5:$G$9,3,FALSE())))) | M10: =IF(K10="","",K10+L10) | N10: =IF(M10="","",G10-M10) | O10: =IF(M10="","",IF(G10>M10,"YES","NO")) | P10: =IF(K10="","",G10/K10)
A11: 9 | B11: =IFERROR(INDEX(RawData_EmpNo,MATCH(C11,RawData_UserName,0)),"") -> 1020 | C11: NtombiYeni | D11: =IFERROR(INDEX(RawData_Team,MATCH(C11,RawData_UserName,0)),"") -> LOC 1 | E11: =COUNTIF(RawData_UserName,C11) -> 12 | F11: =SUMIF(RawData_UserName,C11,RawData_Amount) -> 51811.25 | G11: =IF(E11=12,F11,H11*12) -> 51811.25 | H11: =IFERROR(F11/E11,0) -> 4317.6042 | I11: =IFERROR(AVERAGEIF(RawData_UserName,C11,RawData_Score),"") -> 4.035 | J11: =IF(I11="",Assumptions!$E$6,VLOOKUP(I11,Assumptions!$B$5:$E$9,4,TRUE())) -> Exceptional | L11: =IF(K11="","",IF(OR(J11=Assumptions!$E$5,J11=Assumptions!$E$6),VLOOKUP(J11,Assumptions!$E$5:$F$9,2,FALSE()),MAX(VLOOKUP(J11,Assumptions!$E$5:$F$9,2,FALSE()),K11*VLOOKUP(J11,Assumptions!$E$5:$G$9,3,FALSE())))) | M11: =IF(K11="","",K11+L11) | N11: =IF(M11="","",G11-M11) | O11: =IF(M11="","",IF(G11>M11,"YES","NO")) | P11: =IF(K11="","",G11/K11)
A12: 10 | B12: =IFERROR(INDEX(RawData_EmpNo,MATCH(C12,RawData_UserName,0)),"") -> 1007 | C12: NhanhlaMabunda | D12: =IFERROR(INDEX(RawData_Team,MATCH(C12,RawData_UserName,0)),"") -> LOC 1 | E12: =COUNTIF(RawData_UserName,C12) -> 12 | F12: =SUMIF(RawData_UserName,C12,RawData_Amount) -> 48078.75 | G12: =IF(E12=12,F12,H12*12) -> 48078.75 | H12: =IFERROR(F12/E12,0) -> 4006.5625 | I12: =IFERROR(AVERAGEIF(RawData_UserName,C12,RawData_Score),"") -> 3.795 | J12: =IF(I12="",Assumptions!$E$6,VLOOKUP(I12,Assumptions!$B$5:$E$9,4,TRUE())) -> Exceeds Expectations | L12: =IF(K12="","",IF(OR(J12=Assumptions!$E$5,J12=Assumptions!$E$6),VLOOKUP(J12,Assumptions!$E$5:$F$9,2,FALSE()),MAX(VLOOKUP(J12,Assumptions!$E$5:$F$9,2,FALSE()),K12*VLOOKUP(J12,Assumptions!$E$5:$G$9,3,FALSE())))) | M12: =IF(K12="","",K12+L12) | N12: =IF(M12="","",G12-M12) | O12: =IF(M12="","",IF(G12>M12,"YES","NO")) | P12: =IF(K12="","",G12/K12)
A13: 11 | B13: =IFERROR(INDEX(RawData_EmpNo,MATCH(C13,RawData_UserName,0)),"") -> 1002 | C13: StaceyThomas | D13: =IFERROR(INDEX(RawData_Team,MATCH(C13,RawData_UserName,0)),"") -> LOC 1 | E13: =COUNTIF(RawData_UserName,C13) -> 12 | F13: =SUMIF(RawData_UserName,C13,RawData_Amount) -> 47973.75 | G13: =IF(E13=12,F13,H13*12) -> 47973.75 | H13: =IFERROR(F13/E13,0) -> 3997.8125 | I13: =IFERROR(AVERAGEIF(RawData_UserName,C13,RawData_Score),"") -> 3.9641667 | J13: =IF(I13="",Assumptions!$E$6,VLOOKUP(I13,Assumptions!$B$5:$E$9,4,TRUE())) -> Exceeds Expectations | L13: =IF(K13="","",IF(OR(J13=Assumptions!$E$5,J13=Assumptions!$E$6),VLOOKUP(J13,Assumptions!$E$5:$F$9,2,FALSE()),MAX(VLOOKUP(J13,Assumptions!$E$5:$F$9,2,FALSE()),K13*VLOOKUP(J13,Assumptions!$E$5:$G$9,3,FALSE())))) | M13: =IF(K13="","",K13+L13) | N13: =IF(M13="","",G13-M13) | O13: =IF(M13="","",IF(G13>M13,"YES","NO")) | P13: =IF(K13="","",G13/K13)
A14: 12 | B14: =IFERROR(INDEX(RawData_EmpNo,MATCH(C14,RawData_UserName,0)),"") -> 1003 | C14: MartiniqueLee | D14: =IFERROR(INDEX(RawData_Team,MATCH(C14,RawData_UserName,0)),"") -> LOC 1 | E14: =COUNTIF(RawData_UserName,C14) -> 12 | F14: =SUMIF(RawData_UserName,C14,RawData_Amount) -> 46426.25 | G14: =IF(E14=12,F14,H14*12) -> 46426.25 | H14: =IFERROR(F14/E14,0) -> 3868.8542 | I14: =IFERROR(AVERAGEIF(RawData_UserName,C14,RawData_Score),"") -> 3.965 | J14: =IF(I14="",Assumptions!$E$6,VLOOKUP(I14,Assumptions!$B$5:$E$9,4,TRUE())) -> Exceeds Expectations | L14: =IF(K14="","",IF(OR(J14=Assumptions!$E$5,J14=Assumptions!$E$6),VLOOKUP(J14,Assumptions!$E$5:$F$9,2,FALSE()),MAX(VLOOKUP(J14,Assumptions!$E$5:$F$9,2,FALSE()),K14*VLOOKUP(J14,Assumptions!$E$5:$G$9,3,FALSE())))) | M14: =IF(K14="","",K14+L14) | N14: =IF(M14="","",G14-M14) | O14: =IF(M14="","",IF(G14>M14,"YES","NO")) | P14: =IF(K14="","",G14/K14)
... A71: 69 | B71: =IFERROR(INDEX(RawData_EmpNo,MATCH(C71,RawData_UserName,0)),"") -> 1014 | C71: TeganFrieslaar | D71: =IFERROR(INDEX(RawData_Team,MATCH(C71,RawData_UserName,0)),"") -> LOC 1 | E71: =COUNTIF(RawData_UserName,C71) -> 2 | F71: =SUMIF(RawData_UserName,C71,RawData_Amount) -> 0 | G71: =IF(E71=12,F71,H71*12) -> 0 | H71: =IFERROR(F71/E71,0) -> 0 | I71: =IFERROR(AVERAGEIF(RawData_UserName,C71,RawData_Score),"") | J71: =IF(I71="",Assumptions!$E$6,VLOOKUP(I71,Assumptions!$B$5:$E$9,4,TRUE())) -> Improvement Required | L71: =IF(K71="","",IF(OR(J71=Assumptions!$E$5,J71=Assumptions!$E$6),VLOOKUP(J71,Assumptions!$E$5:$F$9,2,FALSE()),MAX(VLOOKUP(J71,Assumptions!$E$5:$F$9,2,FALSE()),K71*VLOOKUP(J71,Assumptions!$E$5:$G$9,3,FALSE())))) | M71: =IF(K71="","",K71+L71) | N71: =IF(M71="","",G71-M71) | O71: =IF(M71="","",IF(G71>M71,"YES","NO")) | P71: =IF(K71="","",G71/K71)

Sheet Summary Dashboard
A2: Rating
A3: Rating Category | B3: Count | C3: Total OBR | D3: Avg OBR per Employee
A4: Exceptional | B4: =COUNTIF('OBR vs ARR Calculator'!J3:J71,"Exceptional") -> 20 | C4: =SUMIF('OBR vs ARR Calculator'!J3:J71,"Exceptional",'OBR vs ARR Calculator'!F3:F71) -> 438117.69 | D4: =IFERROR(SUMIF('OBR vs ARR Calculator'!J3:J71,"Exceptional",'OBR vs ARR Calculator'!F3:F71)/COUNTIF('OBR vs ARR Calculator'!J3:J71,"Exceptional"),"—") -> 21905.885
A5: Exceeds Expectations | B5: =COUNTIF('OBR vs ARR Calculator'!J3:J71,"Exceeds Expectations") -> 23 | C5: =SUMIF('OBR vs ARR Calculator'!J3:J71,"Exceeds Expectations",'OBR vs ARR Calculator'!F3:F71) -> 458541.2 | D5: =IFERROR(SUMIF('OBR vs ARR Calculator'!J3:J71,"Exceeds Expectations",'OBR vs ARR Calculator'!F3:F71)/COUNTIF('OBR vs ARR Calculator'!J3:J71,"Exceeds Expectations"),"—") -> 19936.574
A6: Meets Expectation | B6: =COUNTIF('OBR vs ARR Calculator'!J3:J71,"Meets Expectation") -> 8 | C6: =SUMIF('OBR vs ARR Calculator'!J3:J71,"Meets Expectation",'OBR vs ARR Calculator'!F3:F71) -> 150699.83 | D6: =IFERROR(SUMIF('OBR vs ARR Calculator'!J3:J71,"Meets Expectation",'OBR vs ARR Calculator'!F3:F71)/COUNTIF('OBR vs ARR Calculator'!J3:J71,"Meets Expectation"),"—") -> 18837.479
A7: Improvement Required | B7: =COUNTIF('OBR vs ARR Calculator'!J3:J71,"Improvement Required") -> 10 | C7: =SUMIF('OBR vs ARR Calculator'!J3:J71,"Improvement Required",'OBR vs ARR Calculator'!F3:F71) -> 257432.5 | D7: =IFERROR(SUMIF('OBR vs ARR Calculator'!J3:J71,"Improvement Required",'OBR vs ARR Calculator'!F3:F71)/COUNTIF('OBR vs ARR Calculator'!J3:J71,"Improvement Required"),"—") -> 25743.25
A8: Significant Improvement Requirement | B8: =COUNTIF('OBR vs ARR Calculator'!J3:J71,"Significant Improvement Requirement") -> 8 | C8: =SUMIF('OBR vs ARR Calculator'!J3:J71,"Significant Improvement Requirement",'OBR vs ARR Calculator'!F3:F71) -> 32800 | D8: =IFERROR(SUMIF('OBR vs ARR Calculator'!J3:J71,"Significant Improvement Requirement",'OBR vs ARR Calculator'!F3:F71)/COUNTIF('OBR vs ARR Calculator'!J3:J71,"Significant Improvement Requirement"),"—") -> 4100
A10: OBR vs ARR Summary
A11: Total OBR Paid (all employees) | C11: =SUM('OBR vs ARR Calculator'!F3:F71) -> 1337591.2
A12: Total ARR Bonus (hypothetical) | C12: =SUMIF('OBR vs ARR Calculator'!K3:K71,"<>",'OBR vs ARR Calculator'!L3:L71) -> 0
A13: Net Difference (Total OBR - Total ARR Bonus) | C13: =IFERROR(C11-C12,"—") -> 1337591.2
A14: Employees where OBR > ARR | C14: =COUNTIF('OBR vs ARR Calculator'!O3:O71,"YES") -> 0
A15: Employees where ARR > OBR | C15: =COUNTIF('OBR vs ARR Calculator'!O3:O71,"NO") -> 0

Sheet Assumptions
A1: ARR Bonus Assumptions
A3: Score Thresholds | E3: Bonus Scale
A4: Rating Category | B4: Min Score (≥) | C4: Max Score (<) | E4: Rating Category | F4: Fixed Floor (R) | G4: % of Salary
A5: Significant Improvement Requirement | B5: 0 | C5: 2.5 | E5: Significant Improvement Requirement | F5: 0 | G5: —
A6: Improvement Required | B6: 2.5 | C6: 3 | E6: Improvement Required | F6: 11500 | G6: —
A7: Meets Expectation | B7: 3 | C7: 3.5 | E7: Meets Expectation | F7: 22500 | G7: 0.075
A8: Exceeds Expectations | B8: 3.5 | C8: 4 | E8: Exceeds Expectations | F8: 27500 | G8: 0.084
A9: Exceptional | B9: 4 | C9: 99 | E9: Exceptional | F9: 32500 | G9: 0.105

Sheet Raw Data
A1: EmpNo | B1: OpsYM | C1: UserName | D1: Team | E1: Division | F1: Score | G1: QA | H1: Model(OBR) | I1: SalesIncentive | J1: Amount | K1: Comment
A2: 1001 | B2: 202502 | C2: DaphneyMmota | D2: LOC 2 | E2: Servicing | F2: 4.06 | G2: 97.87 | H2: 4925 | J2: 4925 | K2: No Change
A3: 1002 | B3: 202502 | C3: StaceyThomas | D3: LOC 1 | E3: Servicing | F3: 3.95 | G3: 95.31 | H3: 3195 | J3: 3195 | K3: No Change
A4: 1003 | B4: 202502 | C4: MartiniqueLee | D4: LOC 1 | E4: Servicing | F4: 4.03 | G4: 99.5 | H4: 3650 | J4: 3650 | K4: No Change
A5: 1004 | B5: 202502 | C5: RenechiaJoseph | D5: LOC 2 | E5: Servicing | F5: 2.65 | G5: 96.12 | H5: 4800 | J5: 4800 | K5: No Change
A6: 1005 | B6: 202502 | C6: TarrynFredericks | D6: Comp 2 | E6: Servicing | F6: 2.81 | G6: 100 | H6: 0 | J6: 0 | K6: No Change
A7: 1006 | B7: 202502 | C7: BrutersMasindi | D7: LOC 2 | E7: Servicing | F7: 4.01 | G7: 99.91 | H7: 4525 | J7: 4525 | K7: No Change
A8: 1007 | B8: 202502 | C8: NhanhlaMabunda | D8: LOC 1 | E8: Servicing | F8: 3.97 | G8: 92.9 | H8: 3357.5 | J8: 3357.5 | K8: No Change
A9: 1008 | B9: 202502 | C9: FrengyMathatho | D9: LOC 1 | E9: Servicing | F9: 2.86 | G9: 100 | H9: 0 | J9: 0 | K9: No Change
A10: 1009 | B10: 202502 | C10: TishkaGan | D10: LOC 1 | E10: Servicing | F10: 2.79 | G10: 93.75 | H10: 5312.5 | J10: 5312.5 | K10: No Change
A11: 1010 | B11: 202502 | C11: NonhlanhlaMasinga | D11: LOC 2 | E11: Servicing | F11: 4.1 | G11: 99.74 | H11: 5300 | J11: 5300 | K11: No Change
A12: 1011 | B12: 202502 | C12: NqobileMagani | D12: Comp 1 | E12: Servicing | F12: 2.91 | G12: 98.46 | H12: 0 | J12: 0 | K12: No Change
A13: 1012 | B13: 202502 | C13: LesegoMotala | D13: Comp 2 | E13: Servicing | F13: 3.52 | G13: 78.36 | H13: 2153 | J13: 2153 | K13: No Change
A14: 1013 | B14: 202502 | C14: NobuhleNgubane | D14: LOC 2 | E14: Servicing | F14: 3.8 | G14: 99.83 | H14: 2300 | J14: 2300 | K14: No Change
A15: 1014 | B15: 202502 | C15: TeganFrieslaar | D15: LOC 1 | E15: Servicing | G15: 100 | H15: 0 | J15: 0 | K15: No Change
A16: 1015 | B16: 202502 | C16: SinikiweHlatswayo | D16: LOC 2 | E16: Servicing | F16: 4.03 | G16: 93.79 | H16: 3495 | J16: 3495 | K16: No Change
A17: 1016 | B17: 202502 | C17: SiveshManikkam | D17: Comp 1 | E17: Servicing | F17: 2.96 | G17: 100 | H17: 5500 | J17: 5500 | K17: No Change
A18: 1017 | B18: 202502 | C18: NormaswaziMhlungu | D18: Comp 2 | E18: Servicing | F18: 3.59 | G18: 98.52 | H18: 975 | J18: 975 | K18: No Change
A19: 1018 | B19: 202502 | C19: PhilisiweMkhize | D19: Comp 1 | E19: Servicing | F19: 3.75 | G19: 99.76 | H19: 1925 | J19: 1925 | K19: No Change
A20: 1019 | B20: 202502 | C20: ChristopherMakhudu | D20: Comp 2 | E20: Servicing | G20: 90.91 | H20: 3000 | J20: 3000 | K20: No Change
A21: 1020 | B21: 202502 | C21: NtombiYeni | D21: LOC 1 | E21: Servicing | F21: 4.16 | G21: 99.88 | H21: 5100 | J21: 5100 | K21: No Change
A22: 1021 | B22: 202502 | C22: ChaseMoses | D22: LOC 2 | E22: Servicing | F22: 2.97 | G22: 84.15 | H22: 3400 | J22: 3400 | K22: No Change
A23: 1022 | B23: 202502 | C23: AjayJayalall | D23: Comp 1 | E23: Servicing | G23: 100 | H23: 0 | J23: 0 | K23: No Change
A24: 1023 | B24: 202502 | C24: CumaLunika | D24: Comp 1 | E24: Servicing | G24: 97.9 | H24: 0 | J24: 0 | K24: No Change
A25: 1024 | B25: 202502 | C25: Jod-AshNaicker | D25: Comp 1 | E25: Servicing | F25: 3.73 | G25: 90 | H25: 1350 | J25: 1350 | K25: No Change
A26: 1025 | B26: 202502 | C26: LancastorHendricks | D26: Comp 1 | E26: Servicing | G26: 100 | H26: 0 | J26: 0 | K26: No Change
A27: 1026 | B27: 202502 | C27: JabulaniNxumalo | D27: Comp 1 | E27: Servicing | F27: 3.67 | G27: 80.83 | H27: 1200 | J27: 1200 | K27: No Change
A28: 1027 | B28: 202502 | C28: ThenjiweMnikathi | D28: Comp 2 | E28: Servicing | F28: 2.95 | G28: 62.18 | H28: 0 | J28: 0 | K28: No Change
A29: 1028 | B29: 202502 | C29: MmaditabaMashimane | D29: Comp 2 | E29: Servicing | F29: 3.76 | G29: 72.49 | H29: 960 | J29: 960 | K29: No Change
A30: 1029 | B30: 202502 | C30: MabelSelesho | D30: LOC 2 | E30: Servicing | F30: 4.04 | G30: 99.76 | H30: 5125 | J30: 5125 | K30: No Change
A31: 1030 | B31: 202502 | C31: BrysonBennette | D31: Comp 2 | E31: Servicing | F31: 3.8 | G31: 99.72 | H31: 2125 | J31: 2125 | K31: No Change
A32: 1031 | B32: 202502 | C32: RosheRaas | D32: Comp 1 | E32: Servicing | F32: 3.35 | G32: 90 | H32: 1237.5 | J32: 1237.5 | K32: No Change
A33: 1032 | B33: 202502 | C33: RamolobeJoel | D33: Comp 2 | E33: Servicing | F33: 3.8 | G33: 100 | H33: 2125 | J33: 2125 | K33: No Change
A34: 1033 | B34: 202502 | C34: NkosingiphileMabaso | D34: Comp 1 | E34: Servicing | F34: 3.71 | G34: 87.07 | H34: 1540 | J34: 1540 | K34: No Change
A35: 1001 | B35: 202502 | C35: DaphneyMmota | D35: LOC 2 | E35: Servicing | F35: 4.06 | G35: 97.87 | H35: 4925 | J35: 4925 | K35: No Change
A36: 1002 | B36: 202502 | C36: StaceyThomas | D36: LOC 1 | E36: Servicing | F36: 3.95 | G36: 95.31 | H36: 3195 | J36: 3195 | K36: No Change
A37: 1003 | B37: 202502 | C37: MartiniqueLee | D37: LOC 1 | E37: Servicing | F37: 4.03 | G37: 99.5 | H37: 3650 | J37: 3650 | K37: No Change
A38: 1004 | B38: 202502 | C38: RenechiaJoseph | D38: LOC 2 | E38: Servicing | F38: 2.65 | G38: 96.12 | H38: 4800 | J38: 4800 | K38: No Change
... A47: 1013 | B47: 202502 | C47: NobuhleNgubane | D47: LOC 2 | E47: Servicing | F47: 3.8 | G47: 99.83 | H47: 2300 | J47: 2300 | K47: No Change
A48: 1014 | B48: 202502 | C48: TeganFrieslaar | D48: LOC 1 | E48: Servicing | G48: 100 | H48: 0 | J48: 0 | K48: No Change
...
